Workbook

Sheet 1
A2: PONDOK PESANTREN DAARUS SALAF
A3: Nomor Statistik Pondok Pesantren : 510033110106
A4: Sekretariat: Masjid Ibnu Taimiyyah, Jl. Pandawa, Karang RT 04 RW 07, Sanggrahan, Grogol, Sukoharjo.
A6: Laporan Penilaian Hifzhul Qur'an
A7: Nama Santri | C7: ABDULLOH ABBAS | M7: Tahun Ajaran | O7: 1446-1447 H / 2025-2026 M
A8: Nomor Induk Santri | C8: 2101102 | M8: Kelas/Jenjang | O8: 5 / ULAA
A9: NISN | C9: - | M9: Semester | O9: GENAP
A11: Juz | B11: Nama Surat | D11: Nilai | G11: Juz | H11: Nama Surat | J11: Nilai | M11: Juz | N11: Nama Surat | P11: Nilai | V11: Rekap Nilai | AZ11: Rerata
D12: K | E12: T | J12: K | K12: T | P12: K | Q12: T | V12: 1 | W12: 2 | X12: 3 | Y12: 4 | Z12: 5 | AA12: 6 | AB12: 7 | AC12: 8 | AD12: 9 | AE12: 10 | AF12: 11 | AG12: 12 | AH12: 13 | AI12: 14 | AJ12: 15 | AK12: 16 | AL12: 17 | AM12: 18 | AN12: 19 | AO12: 20 | AP12: 21 | AQ12: 22 | AR12: 23 | AS12: 24 | AT12: 25 | AU12: 26 | AV12: 27 | AW12: 28 | AX12: 29 | AY12: 30
A14: 1 | B14: al-Fatihah : 1 - 7 | G14: 22 | H14: al-Ahzab : 31 - 73 | M14: 30 | N14: an-Nabaa | P14: 90 | Q14: 70 | U14: Kelancaran | V14: =D14 -> 0 | W14: =D16 -> 0 | X14: =D17 -> 0 | Y14: =D19 -> 0 | Z14: =D21 -> 0 | AA14: =D22 -> 0 | AB14: =D24 -> 0 | AC14: =D26 -> 0 | AD14: =D28 -> 0 | AE14: =D30 -> 0 | AF14: =D32 -> 0 | AG14: =D35 -> 0 | AH14: =D37 -> 0 | AI14: =D40 -> 0 | AJ14: =D42 -> 0 | AK14: =D44 -> 0 | AL14: =D47 -> 0 | AM14: =D49 -> 0 | AN14: =D52 -> 0 | AO14: =D55 -> 0 | AP14: =D58 -> 0 | AQ14: =J14 -> 0 | AR14: =J18 -> 0 | AS14: =J22 -> 0 | AT14: =J25 -> 0 | AU14: =J30 -> 0 | AV14: =J36 -> 90 | AW14: =J43 -> 82 | AX14: =J52 -> 90 | AY14: =P14 -> 90 | AZ14: =AVERAGEIF(V14:AY14,">0") -> 88
B15: al-Baqoroh : 1 - 141 | H15: Saba' | N15: an-Naazi'aat | U15: Tajwid | V15: =E14 -> 0 | W15: =E16 -> 0 | X15: =E17 -> 0 | Y15: =E19 -> 0 | Z15: =E21 -> 0 | AA15: =E22 -> 0 | AB15: =E24 -> 0 | AC15: =E26 -> 0 | AD15: =E28 -> 0 | AE15: =E30 -> 0 | AF15: =E32 -> 0 | AG15: =E35 -> 0 | AH15: =E37 -> 0 | AI15: =E40 -> 0 | AJ15: =E42 -> 0 | AK15: =E44 -> 0 | AL15: =E47 -> 0 | AM15: =E49 -> 0 | AN15: =E52 -> 0 | AO15: =E55 -> 0 | AP15: =E58 -> 0 | AQ15: =K14 -> 0 | AR15: =K18 -> 0 | AS15: =K22 -> 0 | AT15: =K25 -> 0 | AU15: =K30 -> 0 | AV15: =K36 -> 70 | AW15: =K43 -> 70 | AX15: =K52 -> 70 | AY15: =Q14 -> 70 | AZ15: =AVERAGEIF(V15:AY15,">0") -> 70
A16: 2 | B16: al-Baqoroh : 142 - 252 | H16: Fathir | N16: Abasa
A17: 3 | B17: al-Baqoroh : 253 - 286 | H17: Yasin : 1 - 27 | N17: at-Takwiir
B18: Ali Imron : 1 - 91 | G18: 23 | H18: Yasin : 28 - 83 | N18: al-Infithar
A19: 4 | B19: Ali Imron : 92 - 200 | H19: ash-Shafat | N19: al-Muthaffifiin
B20: an-Nisaa : 1 - 23 | H20: Shad | N20: al-Insyiqaq
A21: 5 | B21: an-Nisaa : 24 - 147 | H21: az-Zumar : 1 - 31 | N21: al-Buruuj
A22: 6 | B22: an-Nisaa : 148 - 172 | G22: 24 | H22: az-Zumar : 32 - 75 | N22: ath-Thariq
B23: al-Maidah : 1 - 81 | H23: Ghafir | N23: al-A'laa
A24: 7 | B24: al-Maidah : 82 - 120 | H24: Fusshilat : 1 - 46 | N24: al-Ghasyiyah
B25: al-An'am : 1 - 110 | G25: 25 | H25: Fusshilat : 47 - 54 | N25: al-Fajr
A26: 8 | B26: al-An'am : 111 - 165 | H26: asy-Syuura | N26: al-Balad
B27: al-A'raf : 1 - 87 | H27: az-Zukhruf | N27: asy-Syams
A28: 9 | B28: al-A'raf : 88 - 206 | H28: ad-Dukhaan | N28: al-Lail
B29: al-Anfaal : 1 - 40 | H29: al-Jaatsiyah | N29: adh-Dhuhaa
A30: 10 | B30: al-Anfaal : 41 - 75 | G30: 26 | H30: al-Ahqaf | N30: asy-Syarh
B31: at-Taubah : 1 - 92 | H31: Muhammad | N31: at-Tiin
A32: 11 | B32: at-Taubah : 93 - 129 | H32: al-Fath | N32: al-'Alaq
B33: Yunus : 1 - 109 | H33: al-Hujuraat | N33: al-Qadr
B34: Huud : 1 - 5 | H34: Qaaf | N34: al-Bayyinah
A35: 12 | B35: Huud : 6 - 123 | H35: adz-Dzaariyaat: 1 - 30 | N35: al-Zalzalah
B36: Yusuf : 1 - 52 | G36: 27 | H36: adz-Dzaariyaat: 31 - 60 | J36: 90 | K36: 70 | N36: al-'Aadiyaat
A37: 13 | B37: Yusuf : 53 - 111 | H37: ath-Thuur | N37: al-Qari'ah
B38: ar-Ra'd : 1 - 43 | H38: an-Najm | N38: at-Takatsur
B39: Ibrahim : 1 - 52 | H39: al-Qomar | N39: al-'Ashr
A40: 14 | B40: al-Hijr : 1 - 69 | H40: ar-Rahman | N40: al-Humazah
B41: an-Nahl : 1 - 128 | H41: al-Waaqi'ah | N41: al-Fiil
A42: 15 | B42: al-Israa : 1 - 111 | H42: al-Hadiid | N42: al-Quraisy
B43: al-Kahfi : 1 - 74 | G43: 28 | H43: al-Mujaadilah | J43: 82 | K43: 70 | N43: al-Maa'uun
A44: 16 | B44: al-Kahfi : 75 - 110 | H44: al-Hasyr | N44: al-Kautsar
...

Sheet 2
A2: PONDOK PESANTREN DAARUS SALAF
A3: Nomor Statistik Pondok Pesantren : 510033110106
A4: Sekretariat: Masjid Ibnu Taimiyyah, Jl. Pandawa, Karang RT 04 RW 07, Sanggrahan, Grogol, Sukoharjo.
A6: Laporan Penilaian Hifzhul Qur'an
A7: Nama Santri | C7: FALAH | M7: Tahun Ajaran | O7: 1446-1447 H / 2025-2026 M
A8: Nomor Induk Santri | C8: 2101104 | M8: Kelas/Jenjang | O8: 5 / ULAA
A9: NISN | C9: - | M9: Semester | O9: GENAP
A11: Juz | B11: Nama Surat | D11: Nilai | G11: Juz | H11: Nama Surat | J11: Nilai | M11: Juz | N11: Nama Surat | P11: Nilai | V11: Rekap Nilai | AZ11: Rerata
D12: K | E12: T | J12: K | K12: T | P12: K | Q12: T | V12: 1 | W12: 2 | X12: 3 | Y12: 4 | Z12: 5 | AA12: 6 | AB12: 7 | AC12: 8 | AD12: 9 | AE12: 10 | AF12: 11 | AG12: 12 | AH12: 13 | AI12: 14 | AJ12: 15 | AK12: 16 | AL12: 17 | AM12: 18 | AN12: 19 | AO12: 20 | AP12: 21 | AQ12: 22 | AR12: 23 | AS12: 24 | AT12: 25 | AU12: 26 | AV12: 27 | AW12: 28 | AX12: 29 | AY12: 30
A14: 1 | B14: al-Fatihah : 1 - 7 | G14: 22 | H14: al-Ahzab : 31 - 73 | M14: 30 | N14: an-Nabaa | P14: 90 | Q14: 60 | U14: Kelancaran | V14: =D14 -> 0 | W14: =D16 -> 0 | X14: =D17 -> 0 | Y14: =D19 -> 0 | Z14: =D21 -> 0 | AA14: =D22 -> 0 | AB14: =D24 -> 0 | AC14: =D26 -> 0 | AD14: =D28 -> 0 | AE14: =D30 -> 0 | AF14: =D32 -> 0 | AG14: =D35 -> 0 | AH14: =D37 -> 0 | AI14: =D40 -> 0 | AJ14: =D42 -> 0 | AK14: =D44 -> 0 | AL14: =D47 -> 0 | AM14: =D49 -> 0 | AN14: =D52 -> 0 | AO14: =D55 -> 0 | AP14: =D58 -> 0 | AQ14: =J14 -> 0 | AR14: =J18 -> 0 | AS14: =J22 -> 0 | AT14: =J25 -> 0 | AU14: =J30 -> 0 | AV14: =J36 -> 0 | AW14: =J43 -> 70 | AX14: =J52 -> 85 | AY14: =P14 -> 90 | AZ14: =AVERAGEIF(V14:AY14,">0") -> 81.666667
B15: al-Baqoroh : 1 - 141 | H15: Saba' | N15: an-Naazi'aat | U15: Tajwid | V15: =E14 -> 0 | W15: =E16 -> 0 | X15: =E17 -> 0 | Y15: =E19 -> 0 | Z15: =E21 -> 0 | AA15: =E22 -> 0 | AB15: =E24 -> 0 | AC15: =E26 -> 0 | AD15: =E28 -> 0 | AE15: =E30 -> 0 | AF15: =E32 -> 0 | AG15: =E35 -> 0 | AH15: =E37 -> 0 | AI15: =E40 -> 0 | AJ15: =E42 -> 0 | AK15: =E44 -> 0 | AL15: =E47 -> 0 | AM15: =E49 -> 0 | AN15: =E52 -> 0 | AO15: =E55 -> 0 | AP15: =E58 -> 0 | AQ15: =K14 -> 0 | AR15: =K18 -> 0 | AS15: =K22 -> 0 | AT15: =K25 -> 0 | AU15: =K30 -> 0 | AV15: =K36 -> 0 | AW15: =K43 -> 60 | AX15: =K52 -> 60 | AY15: =Q14 -> 60 | AZ15: =AVERAGEIF(V15:AY15,"<>0") -> 60
A16: 2 | B16: al-Baqoroh : 142 - 252 | H16: Fathir | N16: Abasa
A17: 3 | B17: al-Baqoroh : 253 - 286 | H17: Yasin : 1 - 27 | N17: at-Takwiir
B18: Ali Imron : 1 - 91 | G18: 23 | H18: Yasin : 28 - 83 | N18: al-Infithar
A19: 4 | B19: Ali Imron : 92 - 200 | H19: ash-Shafat | N19: al-Muthaffifiin
B20: an-Nisaa : 1 - 23 | H20: Shad | N20: al-Insyiqaq
A21: 5 | B21: an-Nisaa : 24 - 147 | H21: az-Zumar : 1 - 31 | N21: al-Buruuj
A22: 6 | B22: an-Nisaa : 148 - 172 | G22: 24 | H22: az-Zumar : 32 - 75 | N22: ath-Thariq
B23: al-Maidah : 1 - 81 | H23: Ghafir | N23: al-A'laa
A24: 7 | B24: al-Maidah : 82 - 120 | H24: Fusshilat : 1 - 46 | N24: al-Ghasyiyah
B25: al-An'am : 1 - 110 | G25: 25 | H25: Fusshilat : 47 - 54 | N25: al-Fajr
A26: 8 | B26: al-An'am : 111 - 165 | H26: asy-Syuura | N26: al-Balad
B27: al-A'raf : 1 - 87 | H27: az-Zukhruf | N27: asy-Syams
A28: 9 | B28: al-A'raf : 88 - 206 | H28: ad-Dukhaan | N28: al-Lail
B29: al-Anfaal : 1 - 40 | H29: al-Jaatsiyah | N29: adh-Dhuhaa
A30: 10 | B30: al-Anfaal : 41 - 75 | G30: 26 | H30: al-Ahqaf | N30: asy-Syarh
B31: at-Taubah : 1 - 92 | H31: Muhammad | N31: at-Tiin
A32: 11 | B32: at-Taubah : 93 - 129 | H32: al-Fath | N32: al-'Alaq
B33: Yunus : 1 - 109 | H33: al-Hujuraat | N33: al-Qadr
B34: Huud : 1 - 5 | H34: Qaaf | N34: al-Bayyinah
A35: 12 | B35: Huud : 6 - 123 | H35: adz-Dzaariyaat: 1 - 30 | N35: al-Zalzalah
B36: Yusuf : 1 - 52 | G36: 27 | H36: adz-Dzaariyaat: 31 - 60 | N36: al-'Aadiyaat
A37: 13 | B37: Yusuf : 53 - 111 | H37: ath-Thuur | N37: al-Qari'ah
B38: ar-Ra'd : 1 - 43 | H38: an-Najm | N38: at-Takatsur
B39: Ibrahim : 1 - 52 | H39: al-Qomar | N39: al-'Ashr
A40: 14 | B40: al-Hijr : 1 - 69 | H40: ar-Rahman | N40: al-Humazah
B41: an-Nahl : 1 - 128 | H41: al-Waaqi'ah | N41: al-Fiil
A42: 15 | B42: al-Israa : 1 - 111 | H42: al-Hadiid | N42: al-Quraisy
B43: al-Kahfi : 1 - 74 | G43: 28 | H43: al-Mujaadilah | J43: 70 | K43: 60 | N43: al-Maa'uun
A44: 16 | B44: al-Kahfi : 75 - 110 | H44: al-Hasyr | N44: al-Kautsar
...

Sheet 3
A2: PONDOK PESANTREN DAARUS SALAF
A3: Nomor Statistik Pondok Pesantren : 510033110106
A4: Sekretariat: Masjid Ibnu Taimiyyah, Jl. Pandawa, Karang RT 04 RW 07, Sanggrahan, Grogol, Sukoharjo.
A6: Laporan Penilaian Hifzhul Qur'an
A7: Nama Santri | C7: HAFIZH | M7: Tahun Ajaran | O7: 1446-1447 H / 2025-2026 M
A8: Nomor Induk Santri | C8: 2101105 | M8: Kelas/Jenjang | O8: 5 / ULAA
A9: NISN | C9: - | M9: Semester | O9: GENAP
A11: Juz | B11: Nama Surat | D11: Nilai | G11: Juz | H11: Nama Surat | J11: Nilai | M11: Juz | N11: Nama Surat | P11: Nilai | V11: Rekap Nilai | AZ11: Rerata
D12: K | E12: T | J12: K | K12: T | P12: K | Q12: T | V12: 1 | W12: 2 | X12: 3 | Y12: 4 | Z12: 5 | AA12: 6 | AB12: 7 | AC12: 8 | AD12: 9 | AE12: 10 | AF12: 11 | AG12: 12 | AH12: 13 | AI12: 14 | AJ12: 15 | AK12: 16 | AL12: 17 | AM12: 18 | AN12: 19 | AO12: 20 | AP12: 21 | AQ12: 22 | AR12: 23 | AS12: 24 | AT12: 25 | AU12: 26 | AV12: 27 | AW12: 28 | AX12: 29 | AY12: 30
A14: 1 | B14: al-Fatihah : 1 - 7 | G14: 22 | H14: al-Ahzab : 31 - 73 | M14: 30 | N14: an-Nabaa | P14: 90 | Q14: 70 | U14: Kelancaran | V14: =D14 -> 0 | W14: =D16 -> 0 | X14: =D17 -> 0 | Y14: =D19 -> 0 | Z14: =D21 -> 0 | AA14: =D22 -> 0 | AB14: =D24 -> 0 | AC14: =D26 -> 0 | AD14: =D28 -> 0 | AE14: =D30 -> 0 | AF14: =D32 -> 0 | AG14: =D35 -> 0 | AH14: =D37 -> 0 | AI14: =D40 -> 0 | AJ14: =D42 -> 0 | AK14: =D44 -> 0 | AL14: =D47 -> 0 | AM14: =D49 -> 0 | AN14: =D52 -> 0 | AO14: =D55 -> 0 | AP14: =D58 -> 0 | AQ14: =J14 -> 0 | AR14: =J18 -> 0 | AS14: =J22 -> 60 | AT14: =J25 -> 65 | AU14: =J30 -> 82 | AV14: =J36 -> 76 | AW14: =J43 -> 72 | AX14: =J52 -> 88 | AY14: =P14 -> 90 | AZ14: =AVERAGEIF(V14:AY14,">0") -> 76.142857
B15: al-Baqoroh : 1 - 141 | H15: Saba' | N15: an-Naazi'aat | U15: Tajwid | V15: =E14 -> 0 | W15: =E16 -> 0 | X15: =E17 -> 0 | Y15: =E19 -> 0 | Z15: =E21 -> 0 | AA15: =E22 -> 0 | AB15: =E24 -> 0 | AC15: =E26 -> 0 | AD15: =E28 -> 0 | AE15: =E30 -> 0 | AF15: =E32 -> 0 | AG15: =E35 -> 0 | AH15: =E37 -> 0 | AI15: =E40 -> 0 | AJ15: =E42 -> 0 | AK15: =E44 -> 0 | AL15: =E47 -> 0 | AM15: =E49 -> 0 | AN15: =E52 -> 0 | AO15: =E55 -> 0 | AP15: =E58 -> 0 | AQ15: =K14 -> 0 | AR15: =K18 -> 0 | AS15: =K22 -> 70 | AT15: =K25 -> 70 | AU15: =K30 -> 70 | AV15: =K36 -> 70 | AW15: =K43 -> 70 | AX15: =K52 -> 70 | AY15: =Q14 -> 70 | AZ15: =AVERAGEIF(V15:AY15,">0") -> 70
A16: 2 | B16: al-Baqoroh : 142 - 252 | H16: Fathir | N16: Abasa
A17: 3 | B17: al-Baqoroh : 253 - 286 | H17: Yasin : 1 - 27 | N17: at-Takwiir
B18: Ali Imron : 1 - 91 | G18: 23 | H18: Yasin : 28 - 83 | N18: al-Infithar
A19: 4 | B19: Ali Imron : 92 - 200 | H19: ash-Shafat | N19: al-Muthaffifiin
B20: an-Nisaa : 1 - 23 | H20: Shad | N20: al-Insyiqaq
A21: 5 | B21: an-Nisaa : 24 - 147 | H21: az-Zumar : 1 - 31 | N21: al-Buruuj
A22: 6 | B22: an-Nisaa : 148 - 172 | G22: 24 | H22: az-Zumar : 32 - 75 | J22: 60 | K22: 70 | N22: ath-Thariq
B23: al-Maidah : 1 - 81 | H23: Ghafir | N23: al-A'laa
A24: 7 | B24: al-Maidah : 82 - 120 | H24: Fusshilat : 1 - 46 | N24: al-Ghasyiyah
B25: al-An'am : 1 - 110 | G25: 25 | H25: Fusshilat : 47 - 54 | J25: 65 | K25: 70 | N25: al-Fajr
A26: 8 | B26: al-An'am : 111 - 165 | H26: asy-Syuura | N26: al-Balad
B27: al-A'raf : 1 - 87 | H27: az-Zukhruf | N27: asy-Syams
A28: 9 | B28: al-A'raf : 88 - 206 | H28: ad-Dukhaan | N28: al-Lail
B29: al-Anfaal : 1 - 40 | H29: al-Jaatsiyah | N29: adh-Dhuhaa
A30: 10 | B30: al-Anfaal : 41 - 75 | G30: 26 | H30: al-Ahqaf | J30: 82 | K30: 70 | N30: asy-Syarh
B31: at-Taubah : 1 - 92 | H31: Muhammad | N31: at-Tiin
A32: 11 | B32: at-Taubah : 93 - 129 | H32: al-Fath | N32: al-'Alaq
B33: Yunus : 1 - 109 | H33: al-Hujuraat | N33: al-Qadr
B34: Huud : 1 - 5 | H34: Qaaf | N34: al-Bayyinah
A35: 12 | B35: Huud : 6 - 123 | H35: adz-Dzaariyaat: 1 - 30 | N35: al-Zalzalah
B36: Yusuf : 1 - 52 | G36: 27 | H36: adz-Dzaariyaat: 31 - 60 | J36: 76 | K36: 70 | N36: al-'Aadiyaat
A37: 13 | B37: Yusuf : 53 - 111 | H37: ath-Thuur | N37: al-Qari'ah
B38: ar-Ra'd : 1 - 43 | H38: an-Najm | N38: at-Takatsur
B39: Ibrahim : 1 - 52 | H39: al-Qomar | N39: al-'Ashr
A40: 14 | B40: al-Hijr : 1 - 69 | H40: ar-Rahman | N40: al-Humazah
B41: an-Nahl : 1 - 128 | H41: al-Waaqi'ah | N41: al-Fiil
A42: 15 | B42: al-Israa : 1 - 111 | H42: al-Hadiid | N42: al-Quraisy
B43: al-Kahfi : 1 - 74 | G43: 28 | H43: al-Mujaadilah | J43: 72 | K43: 70 | N43: al-Maa'uun
A44: 16 | B44: al-Kahfi : 75 - 110 | H44: al-Hasyr | N44: al-Kautsar
...

Sheet 4
A2: PONDOK PESANTREN DAARUS SALAF
A3: Nomor Statistik Pondok Pesantren : 510033110106
A4: Sekretariat: Masjid Ibnu Taimiyyah, Jl. Pandawa, Karang RT 04 RW 07, Sanggrahan, Grogol, Sukoharjo.
A6: Laporan Penilaian Hifzhul Qur'an
A7: Nama Santri | C7: HARUN | M7: Tahun Ajaran | O7: 1446-1447 H / 2025-2026 M
A8: Nomor Induk Santri | C8: 2101106 | M8: Kelas/Jenjang | O8: 5 / ULAA
A9: NISN | C9: - | M9: Semester | O9: GENAP
A11: Juz | B11: Nama Surat | D11: Nilai | G11: Juz | H11: Nama Surat | J11: Nilai | M11: Juz | N11: Nama Surat | P11: Nilai | V11: Rekap Nilai | AZ11: Rerata
D12: K | E12: T | J12: K | K12: T | P12: K | Q12: T | V12: 1 | W12: 2 | X12: 3 | Y12: 4 | Z12: 5 | AA12: 6 | AB12: 7 | AC12: 8 | AD12: 9 | AE12: 10 | AF12: 11 | AG12: 12 | AH12: 13 | AI12: 14 | AJ12: 15 | AK12: 16 | AL12: 17 | AM12: 18 | AN12: 19 | AO12: 20 | AP12: 21 | AQ12: 22 | AR12: 23 | AS12: 24 | AT12: 25 | AU12: 26 | AV12: 27 | AW12: 28 | AX12: 29 | AY12: 30
A14: 1 | B14: al-Fatihah : 1 - 7 | G14: 22 | H14: al-Ahzab : 31 - 73 | J14: 50 | K14: 70 | M14: 30 | N14: an-Nabaa | P14: 90 | Q14: 70 | U14: Kelancaran | V14: =D14 -> 0 | W14: =D16 -> 0 | X14: =D17 -> 0 | Y14: =D19 -> 0 | Z14: =D21 -> 0 | AA14: =D22 -> 0 | AB14: =D24 -> 0 | AC14: =D26 -> 0 | AD14: =D28 -> 0 | AE14: =D30 -> 0 | AF14: =D32 -> 0 | AG14: =D35 -> 0 | AH14: =D37 -> 0 | AI14: =D40 -> 0 | AJ14: =D42 -> 0 | AK14: =D44 -> 0 | AL14: =D47 -> 0 | AM14: =D49 -> 0 | AN14: =D52 -> 0 | AO14: =D55 -> 0 | AP14: =D58 -> 0 | AQ14: =J14 -> 50 | AR14: =J18 -> 57 | AS14: =J22 -> 70 | AT14: =J25 -> 67 | AU14: =J30 -> 86 | AV14: =J36 -> 90 | AW14: =J43 -> 73 | AX14: =J52 -> 90 | AY14: =P14 -> 90 | AZ14: =AVERAGEIF(V14:AY14,">0") -> 74.777778
B15: al-Baqoroh : 1 - 141 | H15: Saba' | N15: an-Naazi'aat | U15: Tajwid | V15: =E14 -> 0 | W15: =E16 -> 0 | X15: =E17 -> 0 | Y15: =E19 -> 0 | Z15: =E21 -> 0 | AA15: =E22 -> 0 | AB15: =E24 -> 0 | AC15: =E26 -> 0 | AD15: =E28 -> 0 | AE15: =E30 -> 0 | AF15: =E32 -> 0 | AG15: =E35 -> 0 | AH15: =E37 -> 0 | AI15: =E40 -> 0 | AJ15: =E42 -> 0 | AK15: =E44 -> 0 | AL15: =E47 -> 0 | AM15: =E49 -> 0 | AN15: =E52 -> 0 | AO15: =E55 -> 0 | AP15: =E58 -> 0 | AQ15: =K14 -> 70 | AR15: =K18 -> 60 | AS15: =K22 -> 70 | AT15: =K25 -> 70 | AU15: =K30 -> 70 | AV15: =K36 -> 70 | AW15: =K43 -> 70 | AX15: =K52 -> 70 | AY15: =Q14 -> 70 | AZ15: =AVERAGEIF(V15:AY15,"<>0") -> 68.888889
A16: 2 | B16: al-Baqoroh : 142 - 252 | H16: Fathir | N16: Abasa
A17: 3 | B17: al-Baqoroh : 253 - 286 | H17: Yasin : 1 - 27 | N17: at-Takwiir
B18: Ali Imron : 1 - 91 | G18: 23 | H18: Yasin : 28 - 83 | J18: 57 | K18: 60 | N18: al-Infithar
A19: 4 | B19: Ali Imron : 92 - 200 | H19: ash-Shafat | N19: al-Muthaffifiin
B20: an-Nisaa : 1 - 23 | H20: Shad | N20: al-Insyiqaq
A21: 5 | B21: an-Nisaa : 24 - 147 | H21: az-Zumar : 1 - 31 | N21: al-Buruuj
A22: 6 | B22: an-Nisaa : 148 - 172 | G22: 24 | H22: az-Zumar : 32 - 75 | J22: 70 | K22: 70 | N22: ath-Thariq
B23: al-Maidah : 1 - 81 | H23: Ghafir | N23: al-A'laa
A24: 7 | B24: al-Maidah : 82 - 120 | H24: Fusshilat : 1 - 46 | N24: al-Ghasyiyah
B25: al-An'am : 1 - 110 | G25: 25 | H25: Fusshilat : 47 - 54 | J25: 67 | K25: 70 | N25: al-Fajr
A26: 8 | B26: al-An'am : 111 - 165 | H26: asy-Syuura | N26: al-Balad
B27: al-A'raf : 1 - 87 | H27: az-Zukhruf | N27: asy-Syams
A28: 9 | B28: al-A'raf : 88 - 206 | H28: ad-Dukhaan | N28: al-Lail
B29: al-Anfaal : 1 - 40 | H29: al-Jaatsiyah | N29: adh-Dhuhaa
A30: 10 | B30: al-Anfaal : 41 - 75 | G30: 26 | H30: al-Ahqaf | J30: 86 | K30: 70 | N30: asy-Syarh
B31: at-Taubah : 1 - 92 | H31: Muhammad | N31: at-Tiin
A32: 11 | B32: at-Taubah : 93 - 129 | H32: al-Fath | N32: al-'Alaq
B33: Yunus : 1 - 109 | H33: al-Hujuraat | N33: al-Qadr
B34: Huud : 1 - 5 | H34: Qaaf | N34: al-Bayyinah
A35: 12 | B35: Huud : 6 - 123 | H35: adz-Dzaariyaat: 1 - 30 | N35: al-Zalzalah
B36: Yusuf : 1 - 52 | G36: 27 | H36: adz-Dzaariyaat: 31 - 60 | J36: 90 | K36: 70 | N36: al-'Aadiyaat
A37: 13 | B37: Yusuf : 53 - 111 | H37: ath-Thuur | N37: al-Qari'ah
B38: ar-Ra'd : 1 - 43 | H38: an-Najm | N38: at-Takatsur
B39: Ibrahim : 1 - 52 | H39: al-Qomar | N39: al-'Ashr
A40: 14 | B40: al-Hijr : 1 - 69 | H40: ar-Rahman | N40: al-Humazah
B41: an-Nahl : 1 - 128 | H41: al-Waaqi'ah | N41: al-Fiil
A42: 15 | B42: al-Israa : 1 - 111 | H42: al-Hadiid | N42: al-Quraisy
B43: al-Kahfi : 1 - 74 | G43: 28 | H43: al-Mujaadilah | J43: 73 | K43: 70 | N43: al-Maa'uun
A44: 16 | B44: al-Kahfi : 75 - 110 | H44: al-Hasyr | N44: al-Kautsar
...

Sheet 5
A2: PONDOK PESANTREN DAARUS SALAF
A3: Nomor Statistik Pondok Pesantren : 510033110106
A4: Sekretariat: Masjid Ibnu Taimiyyah, Jl. Pandawa, Karang RT 04 RW 07, Sanggrahan, Grogol, Sukoharjo.
A6: Laporan Penilaian Hifzhul Qur'an
A7: Nama Santri | C7: HASAN HAFIZHUDDIN | M7: Tahun Ajaran | O7: 1446-1447 H / 2025-2026 M
A8: Nomor Induk Santri | C8: 2101107 | M8: Kelas/Jenjang | O8: 5 / ULAA
A9: NISN | C9: - | M9: Semester | O9: GENAP
A11: Juz | B11: Nama Surat | D11: Nilai | G11: Juz | H11: Nama Surat | J11: Nilai | M11: Juz | N11: Nama Surat | P11: Nilai | V11: Rekap Nilai | AZ11: Rerata
D12: K | E12: T | J12: K | K12: T | P12: K | Q12: T | V12: 1 | W12: 2 | X12: 3 | Y12: 4 | Z12: 5 | AA12: 6 | AB12: 7 | AC12: 8 | AD12: 9 | AE12: 10 | AF12: 11 | AG12: 12 | AH12: 13 | AI12: 14 | AJ12: 15 | AK12: 16 | AL12: 17 | AM12: 18 | AN12: 19 | AO12: 20 | AP12: 21 | AQ12: 22 | AR12: 23 | AS12: 24 | AT12: 25 | AU12: 26 | AV12: 27 | AW12: 28 | AX12: 29 | AY12: 30
A14: 1 | B14: al-Fatihah : 1 - 7 | G14: 22 | H14: al-Ahzab : 31 - 73 | M14: 30 | N14: an-Nabaa | P14: 90 | Q14: 65 | U14: Kelancaran | V14: =D14 -> 0 | W14: =D16 -> 0 | X14: =D17 -> 0 | Y14: =D19 -> 0 | Z14: =D21 -> 0 | AA14: =D22 -> 0 | AB14: =D24 -> 0 | AC14: =D26 -> 0 | AD14: =D28 -> 0 | AE14: =D30 -> 0 | AF14: =D32 -> 0 | AG14: =D35 -> 0 | AH14: =D37 -> 0 | AI14: =D40 -> 0 | AJ14: =D42 -> 0 | AK14: =D44 -> 0 | AL14: =D47 -> 0 | AM14: =D49 -> 0 | AN14: =D52 -> 0 | AO14: =D55 -> 0 | AP14: =D58 -> 0 | AQ14: =J14 -> 0 | AR14: =J18 -> 0 | AS14: =J22 -> 0 | AT14: =J25 -> 0 | AU14: =J30 -> 0 | AV14: =J36 -> 80 | AW14: =J43 -> 85 | AX14: =J52 -> 85 | AY14: =P14 -> 90 | AZ14: =AVERAGEIF(V14:AY14,">0") -> 85
B15: al-Baqoroh : 1 - 141 | H15: Saba' | N15: an-Naazi'aat | U15: Tajwid | V15: =E14 -> 0 | W15: =E16 -> 0 | X15: =E17 -> 0 | Y15: =E19 -> 0 | Z15: =E21 -> 0 | AA15: =E22 -> 0 | AB15: =E24 -> 0 | AC15: =E26 -> 0 | AD15: =E28 -> 0 | AE15: =E30 -> 0 | AF15: =E32 -> 0 | AG15: =E35 -> 0 | AH15: =E37 -> 0 | AI15: =E40 -> 0 | AJ15: =E42 -> 0 | AK15: =E44 -> 0 | AL15: =E47 -> 0 | AM15: =E49 -> 0 | AN15: =E52 -> 0 | AO15: =E55 -> 0 | AP15: =E58 -> 0 | AQ15: =K14 -> 0 | AR15: =K18 -> 0 | AS15: =K22 -> 0 | AT15: =K25 -> 0 | AU15: =K30 -> 0 | AV15: =K36 -> 65 | AW15: =K43 -> 65 | AX15: =K52 -> 65 | AY15: =Q14 -> 65 | AZ15: =AVERAGEIF(V15:AY15,">0") -> 65
A16: 2 | B16: al-Baqoroh : 142 - 252 | H16: Fathir | N16: Abasa
A17: 3 | B17: al-Baqoroh : 253 - 286 | H17: Yasin : 1 - 27 | N17: at-Takwiir
B18: Ali Imron : 1 - 91 | G18: 23 | H18: Yasin : 28 - 83 | N18: al-Infithar
A19: 4 | B19: Ali Imron : 92 - 200 | H19: ash-Shafat | N19: al-Muthaffifiin
B20: an-Nisaa : 1 - 23 | H20: Shad | N20: al-Insyiqaq
A21: 5 | B21: an-Nisaa : 24 - 147 | H21: az-Zumar : 1 - 31 | N21: al-Buruuj
A22: 6 | B22: an-Nisaa : 148 - 172 | G22: 24 | H22: az-Zumar : 32 - 75 | N22: ath-Thariq
B23: al-Maidah : 1 - 81 | H23: Ghafir | N23: al-A'laa
A24: 7 | B24: al-Maidah : 82 - 120 | H24: Fusshilat : 1 - 46 | N24: al-Ghasyiyah
B25: al-An'am : 1 - 110 | G25: 25 | H25: Fusshilat : 47 - 54 | N25: al-Fajr
A26: 8 | B26: al-An'am : 111 - 165 | H26: asy-Syuura | N26: al-Balad
B27: al-A'raf : 1 - 87 | H27: az-Zukhruf | N27: asy-Syams
A28: 9 | B28: al-A'raf : 88 - 206 | H28: ad-Dukhaan | N28: al-Lail
B29: al-Anfaal : 1 - 40 | H29: al-Jaatsiyah | N29: adh-Dhuhaa
A30: 10 | B30: al-Anfaal : 41 - 75 | G30: 26 | H30: al-Ahqaf | N30: asy-Syarh
B31: at-Taubah : 1 - 92 | H31: Muhammad | N31: at-Tiin
A32: 11 | B32: at-Taubah : 93 - 129 | H32: al-Fath | N32: al-'Alaq
B33: Yunus : 1 - 109 | H33: al-Hujuraat | N33: al-Qadr
B34: Huud : 1 - 5 | H34: Qaaf | N34: al-Bayyinah
A35: 12 | B35: Huud : 6 - 123 | H35: adz-Dzaariyaat: 1 - 30 | N35: al-Zalzalah
B36: Yusuf : 1 - 52 | G36: 27 | H36: adz-Dzaariyaat: 31 - 60 | J36: 80 | K36: 65 | N36: al-'Aadiyaat
A37: 13 | B37: Yusuf : 53 - 111 | H37: ath-Thuur | N37: al-Qari'ah
B38: ar-Ra'd : 1 - 43 | H38: an-Najm | N38: at-Takatsur
B39: Ibrahim : 1 - 52 | H39: al-Qomar | N39: al-'Ashr
A40: 14 | B40: al-Hijr : 1 - 69 | H40: ar-Rahman | N40: al-Humazah
B41: an-Nahl : 1 - 128 | H41: al-Waaqi'ah | N41: al-Fiil
A42: 15 | B42: al-Israa : 1 - 111 | H42: al-Hadiid | N42: al-Quraisy
B43: al-Kahfi : 1 - 74 | G43: 28 | H43: al-Mujaadilah | J43: 85 | K43: 65 | N43: al-Maa'uun
A44: 16 | B44: al-Kahfi : 75 - 110 | H44: al-Hasyr | N44: al-Kautsar
...

Sheet 6
A2: PONDOK PESANTREN DAARUS SALAF
A3: Nomor Statistik Pondok Pesantren : 510033110106
A4: Sekretariat: Masjid Ibnu Taimiyyah, Jl. Pandawa, Karang RT 04 RW 07, Sanggrahan, Grogol, Sukoharjo.
A6: Laporan Penilaian Hifzhul Qur'an
A7: Nama Santri | C7: IBROHIM AL ATSARY | M7: Tahun Ajaran | O7: 1446-1447 H / 2025-2026 M
A8: Nomor Induk Santri | C8: 2101108 | M8: Kelas/Jenjang | O8: 5 / ULAA
A9: NISN | C9: - | M9: Semester | O9: GENAP
A11: Juz | B11: Nama Surat | D11: Nilai | G11: Juz | H11: Nama Surat | J11: Nilai | M11: Juz | N11: Nama Surat | P11: Nilai | V11: Rekap Nilai | AZ11: Rerata
D12: K | E12: T | J12: K | K12: T | P12: K | Q12: T | V12: 1 | W12: 2 | X12: 3 | Y12: 4 | Z12: 5 | AA12: 6 | AB12: 7 | AC12: 8 | AD12: 9 | AE12: 10 | AF12: 11 | AG12: 12 | AH12: 13 | AI12: 14 | AJ12: 15 | AK12: 16 | AL12: 17 | AM12: 18 | AN12: 19 | AO12: 20 | AP12: 21 | AQ12: 22 | AR12: 23 | AS12: 24 | AT12: 25 | AU12: 26 | AV12: 27 | AW12: 28 | AX12: 29 | AY12: 30
A14: 1 | B14: al-Fatihah : 1 - 7 | G14: 22 | H14: al-Ahzab : 31 - 73 | M14: 30 | N14: an-Nabaa | P14: 64 | Q14: 60 | U14: Kelancaran | V14: =D14 -> 0 | W14: =D16 -> 0 | X14: =D17 -> 0 | Y14: =D19 -> 0 | Z14: =D21 -> 0 | AA14: =D22 -> 0 | AB14: =D24 -> 0 | AC14: =D26 -> 0 | AD14: =D28 -> 0 | AE14: =D30 -> 0 | AF14: =D32 -> 0 | AG14: =D35 -> 0 | AH14: =D37 -> 0 | AI14: =D40 -> 0 | AJ14: =D42 -> 0 | AK14: =D44 -> 0 | AL14: =D47 -> 0 | AM14: =D49 -> 0 | AN14: =D52 -> 0 | AO14: =D55 -> 0 | AP14: =D58 -> 0 | AQ14: =J14 -> 0 | AR14: =J18 -> 0 | AS14: =J22 -> 0 | AT14: =J25 -> 0 | AU14: =J30 -> 0 | AV14: =J36 -> 0 | AW14: =J43 -> 0 | AX14: =J52 -> 59 | AY14: =P14 -> 64 | AZ14: =AVERAGEIF(V14:AY14,">0") -> 61.5
B15: al-Baqoroh : 1 - 141 | H15: Saba' | N15: an-Naazi'aat | U15: Tajwid | V15: =E14 -> 0 | W15: =E16 -> 0 | X15: =E17 -> 0 | Y15: =E19 -> 0 | Z15: =E21 -> 0 | AA15: =E22 -> 0 | AB15: =E24 -> 0 | AC15: =E26 -> 0 | AD15: =E28 -> 0 | AE15: =E30 -> 0 | AF15: =E32 -> 0 | AG15: =E35 -> 0 | AH15: =E37 -> 0 | AI15: =E40 -> 0 | AJ15: =E42 -> 0 | AK15: =E44 -> 0 | AL15: =E47 -> 0 | AM15: =E49 -> 0 | AN15: =E52 -> 0 | AO15: =E55 -> 0 | AP15: =E58 -> 0 | AQ15: =K14 -> 0 | AR15: =K18 -> 0 | AS15: =K22 -> 0 | AT15: =K25 -> 0 | AU15: =K30 -> 0 | AV15: =K36 -> 0 | AW15: =K43 -> 0 | AX15: =K52 -> 60 | AY15: =Q14 -> 60 | AZ15: =AVERAGEIF(V15:AY15,"<>0") -> 60
A16: 2 | B16: al-Baqoroh : 142 - 252 | H16: Fathir | N16: Abasa
A17: 3 | B17: al-Baqoroh : 253 - 286 | H17: Yasin : 1 - 27 | N17: at-Takwiir
B18: Ali Imron : 1 - 91 | G18: 23 | H18: Yasin : 28 - 83 | N18: al-Infithar
A19: 4 | B19: Ali Imron : 92 - 200 | H19: ash-Shafat | N19: al-Muthaffifiin
B20: an-Nisaa : 1 - 23 | H20: Shad | N20: al-Insyiqaq
A21: 5 | B21: an-Nisaa : 24 - 147 | H21: az-Zumar : 1 - 31 | N21: al-Buruuj
A22: 6 | B22: an-Nisaa : 148 - 172 | G22: 24 | H22: az-Zumar : 32 - 75 | N22: ath-Thariq
B23: al-Maidah : 1 - 81 | H23: Ghafir | N23: al-A'laa
A24: 7 | B24: al-Maidah : 82 - 120 | H24: Fusshilat : 1 - 46 | N24: al-Ghasyiyah
B25: al-An'am : 1 - 110 | G25: 25 | H25: Fusshilat : 47 - 54 | N25: al-Fajr
A26: 8 | B26: al-An'am : 111 - 165 | H26: asy-Syuura | N26: al-Balad
B27: al-A'raf : 1 - 87 | H27: az-Zukhruf | N27: asy-Syams
A28: 9 | B28: al-A'raf : 88 - 206 | H28: ad-Dukhaan | N28: al-Lail
B29: al-Anfaal : 1 - 40 | H29: al-Jaatsiyah | N29: adh-Dhuhaa
A30: 10 | B30: al-Anfaal : 41 - 75 | G30: 26 | H30: al-Ahqaf | N30: asy-Syarh
B31: at-Taubah : 1 - 92 | H31: Muhammad | N31: at-Tiin
A32: 11 | B32: at-Taubah : 93 - 129 | H32: al-Fath | N32: al-'Alaq
B33: Yunus : 1 - 109 | H33: al-Hujuraat | N33: al-Qadr
B34: Huud : 1 - 5 | H34: Qaaf | N34: al-Bayyinah
A35: 12 | B35: Huud : 6 - 123 | H35: adz-Dzaariyaat: 1 - 30 | N35: al-Zalzalah
B36: Yusuf : 1 - 52 | G36: 27 | H36: adz-Dzaariyaat: 31 - 60 | N36: al-'Aadiyaat
A37: 13 | B37: Yusuf : 53 - 111 | H37: ath-Thuur | N37: al-Qari'ah
B38: ar-Ra'd : 1 - 43 | H38: an-Najm | N38: at-Takatsur
B39: Ibrahim : 1 - 52 | H39: al-Qomar | N39: al-'Ashr
A40: 14 | B40: al-Hijr : 1 - 69 | H40: ar-Rahman | N40: al-Humazah
B41: an-Nahl : 1 - 128 | H41: al-Waaqi'ah | N41: al-Fiil
A42: 15 | B42: al-Israa : 1 - 111 | H42: al-Hadiid | N42: al-Quraisy
B43: al-Kahfi : 1 - 74 | G43: 28 | H43: al-Mujaadilah | N43: al-Maa'uun
A44: 16 | B44: al-Kahfi : 75 - 110 | H44: al-Hasyr | N44: al-Kautsar
...

Sheet 7
A2: PONDOK PESANTREN DAARUS SALAF
A3: Nomor Statistik Pondok Pesantren : 510033110106
A4: Sekretariat: Masjid Ibnu Taimiyyah, Jl. Pandawa, Karang RT 04 RW 07, Sanggrahan, Grogol, Sukoharjo.
A6: Laporan Penilaian Hifzhul Qur'an
A7: Nama Santri | C7: M. AUZAI ZIYAD | M7: Tahun Ajaran | O7: 1446-1447 H / 2025-2026 M
A8: Nomor Induk Santri | C8: 2101110 | M8: Kelas/Jenjang | O8: 5 / ULAA
A9: NISN | C9: - | M9: Semester | O9: GENAP
A11: Juz | B11: Nama Surat | D11: Nilai | G11: Juz | H11: Nama Surat | J11: Nilai | M11: Juz | N11: Nama Surat | P11: Nilai | V11: Rekap Nilai | AZ11: Rerata
D12: K | E12: T | J12: K | K12: T | P12: K | Q12: T | V12: 1 | W12: 2 | X12: 3 | Y12: 4 | Z12: 5 | AA12: 6 | AB12: 7 | AC12: 8 | AD12: 9 | AE12: 10 | AF12: 11 | AG12: 12 | AH12: 13 | AI12: 14 | AJ12: 15 | AK12: 16 | AL12: 17 | AM12: 18 | AN12: 19 | AO12: 20 | AP12: 21 | AQ12: 22 | AR12: 23 | AS12: 24 | AT12: 25 | AU12: 26 | AV12: 27 | AW12: 28 | AX12: 29 | AY12: 30
A14: 1 | B14: al-Fatihah : 1 - 7 | G14: 22 | H14: al-Ahzab : 31 - 73 | M14: 30 | N14: an-Nabaa | P14: 80 | Q14: 60 | U14: Kelancaran | V14: =D14 -> 0 | W14: =D16 -> 0 | X14: =D17 -> 0 | Y14: =D19 -> 0 | Z14: =D21 -> 0 | AA14: =D22 -> 0 | AB14: =D24 -> 0 | AC14: =D26 -> 0 | AD14: =D28 -> 0 | AE14: =D30 -> 0 | AF14: =D32 -> 0 | AG14: =D35 -> 0 | AH14: =D37 -> 0 | AI14: =D40 -> 0 | AJ14: =D42 -> 0 | AK14: =D44 -> 0 | AL14: =D47 -> 0 | AM14: =D49 -> 0 | AN14: =D52 -> 0 | AO14: =D55 -> 0 | AP14: =D58 -> 0 | AQ14: =J14 -> 0 | AR14: =J18 -> 0 | AS14: =J22 -> 0 | AT14: =J25 -> 0 | AU14: =J30 -> 0 | AV14: =J36 -> 0 | AW14: =J43 -> 53 | AX14: =J52 -> 80 | AY14: =P14 -> 80 | AZ14: =AVERAGEIF(V14:AY14,">0") -> 71
B15: al-Baqoroh : 1 - 141 | H15: Saba' | N15: an-Naazi'aat | U15: Tajwid | V15: =E14 -> 0 | W15: =E16 -> 0 | X15: =E17 -> 0 | Y15: =E19 -> 0 | Z15: =E21 -> 0 | AA15: =E22 -> 0 | AB15: =E24 -> 0 | AC15: =E26 -> 0 | AD15: =E28 -> 0 | AE15: =E30 -> 0 | AF15: =E32 -> 0 | AG15: =E35 -> 0 | AH15: =E37 -> 0 | AI15: =E40 -> 0 | AJ15: =E42 -> 0 | AK15: =E44 -> 0 | AL15: =E47 -> 0 | AM15: =E49 -> 0 | AN15: =E52 -> 0 | AO15: =E55 -> 0 | AP15: =E58 -> 0 | AQ15: =K14 -> 0 | AR15: =K18 -> 0 | AS15: =K22 -> 0 | AT15: =K25 -> 0 | AU15: =K30 -> 0 | AV15: =K36 -> 0 | AW15: =K43 -> 60 | AX15: =K52 -> 60 | AY15: =Q14 -> 60 | AZ15: =AVERAGEIF(V15:AY15,">0") -> 60
A16: 2 | B16: al-Baqoroh : 142 - 252 | H16: Fathir | N16: Abasa
A17: 3 | B17: al-Baqoroh : 253 - 286 | H17: Yasin : 1 - 27 | N17: at-Takwiir
B18: Ali Imron : 1 - 91 | G18: 23 | H18: Yasin : 28 - 83 | N18: al-Infithar
A19: 4 | B19: Ali Imron : 92 - 200 | H19: ash-Shafat | N19: al-Muthaffifiin
B20: an-Nisaa : 1 - 23 | H20: Shad | N20: al-Insyiqaq
A21: 5 | B21: an-Nisaa : 24 - 147 | H21: az-Zumar : 1 - 31 | N21: al-Buruuj
A22: 6 | B22: an-Nisaa : 148 - 172 | G22: 24 | H22: az-Zumar : 32 - 75 | N22: ath-Thariq
B23: al-Maidah : 1 - 81 | H23: Ghafir | N23: al-A'laa
A24: 7 | B24: al-Maidah : 82 - 120 | H24: Fusshilat : 1 - 46 | N24: al-Ghasyiyah
B25: al-An'am : 1 - 110 | G25: 25 | H25: Fusshilat : 47 - 54 | N25: al-Fajr
A26: 8 | B26: al-An'am : 111 - 165 | H26: asy-Syuura | N26: al-Balad
B27: al-A'raf : 1 - 87 | H27: az-Zukhruf | N27: asy-Syams
A28: 9 | B28: al-A'raf : 88 - 206 | H28: ad-Dukhaan | N28: al-Lail
B29: al-Anfaal : 1 - 40 | H29: al-Jaatsiyah | N29: adh-Dhuhaa
A30: 10 | B30: al-Anfaal : 41 - 75 | G30: 26 | H30: al-Ahqaf | N30: asy-Syarh
B31: at-Taubah : 1 - 92 | H31: Muhammad | N31: at-Tiin
A32: 11 | B32: at-Taubah : 93 - 129 | H32: al-Fath | N32: al-'Alaq
B33: Yunus : 1 - 109 | H33: al-Hujuraat | N33: al-Qadr
B34: Huud : 1 - 5 | H34: Qaaf | N34: al-Bayyinah
A35: 12 | B35: Huud : 6 - 123 | H35: adz-Dzaariyaat: 1 - 30 | N35: al-Zalzalah
B36: Yusuf : 1 - 52 | G36: 27 | H36: adz-Dzaariyaat: 31 - 60 | N36: al-'Aadiyaat
A37: 13 | B37: Yusuf : 53 - 111 | H37: ath-Thuur | N37: al-Qari'ah
B38: ar-Ra'd : 1 - 43 | H38: an-Najm | N38: at-Takatsur
B39: Ibrahim : 1 - 52 | H39: al-Qomar | N39: al-'Ashr
A40: 14 | B40: al-Hijr : 1 - 69 | H40: ar-Rahman | N40: al-Humazah
B41: an-Nahl : 1 - 128 | H41: al-Waaqi'ah | N41: al-Fiil
A42: 15 | B42: al-Israa : 1 - 111 | H42: al-Hadiid | N42: al-Quraisy
B43: al-Kahfi : 1 - 74 | G43: 28 | H43: al-Mujaadilah | J43: 53 | K43: 60 | N43: al-Maa'uun
A44: 16 | B44: al-Kahfi : 75 - 110 | H44: al-Hasyr | N44: al-Kautsar
...

Sheet 8
A2: PONDOK PESANTREN DAARUS SALAF
A3: Nomor Statistik Pondok Pesantren : 510033110106
A4: Sekretariat: Masjid Ibnu Taimiyyah, Jl. Pandawa, Karang RT 04 RW 07, Sanggrahan, Grogol, Sukoharjo.
A6: Laporan Penilaian Hifzhul Qur'an
A7: Nama Santri | C7: MUHAMMAD FAKIH | M7: Tahun Ajaran | O7: 1446-1447 H / 2025-2026 M
A8: Nomor Induk Santri | C8: 2101111 | M8: Kelas/Jenjang | O8: 5 / ULAA
A9: NISN | C9: - | M9: Semester | O9: GENAP
A11: Juz | B11: Nama Surat | D11: Nilai | G11: Juz | H11: Nama Surat | J11: Nilai | M11: Juz | N11: Nama Surat | P11: Nilai | V11: Rekap Nilai | AZ11: Rerata
D12: K | E12: T | J12: K | K12: T | P12: K | Q12: T | V12: 1 | W12: 2 | X12: 3 | Y12: 4 | Z12: 5 | AA12: 6 | AB12: 7 | AC12: 8 | AD12: 9 | AE12: 10 | AF12: 11 | AG12: 12 | AH12: 13 | AI12: 14 | AJ12: 15 | AK12: 16 | AL12: 17 | AM12: 18 | AN12: 19 | AO12: 20 | AP12: 21 | AQ12: 22 | AR12: 23 | AS12: 24 | AT12: 25 | AU12: 26 | AV12: 27 | AW12: 28 | AX12: 29 | AY12: 30
A14: 1 | B14: al-Fatihah : 1 - 7 | G14: 22 | H14: al-Ahzab : 31 - 73 | M14: 30 | N14: an-Nabaa | P14: 85 | Q14: 65 | U14: Kelancaran | V14: =D14 -> 0 | W14: =D16 -> 0 | X14: =D17 -> 0 | Y14: =D19 -> 0 | Z14: =D21 -> 0 | AA14: =D22 -> 0 | AB14: =D24 -> 0 | AC14: =D26 -> 0 | AD14: =D28 -> 0 | AE14: =D30 -> 0 | AF14: =D32 -> 0 | AG14: =D35 -> 0 | AH14: =D37 -> 0 | AI14: =D40 -> 0 | AJ14: =D42 -> 0 | AK14: =D44 -> 0 | AL14: =D47 -> 0 | AM14: =D49 -> 0 | AN14: =D52 -> 0 | AO14: =D55 -> 0 | AP14: =D58 -> 0 | AQ14: =J14 -> 0 | AR14: =J18 -> 0 | AS14: =J22 -> 0 | AT14: =J25 -> 0 | AU14: =J30 -> 0 | AV14: =J36 -> 0 | AW14: =J43 -> 0 | AX14: =J52 -> 75 | AY14: =P14 -> 85 | AZ14: =AVERAGEIF(V14:AY14,">0") -> 80
B15: al-Baqoroh : 1 - 141 | H15: Saba' | N15: an-Naazi'aat | U15: Tajwid | V15: =E14 -> 0 | W15: =E16 -> 0 | X15: =E17 -> 0 | Y15: =E19 -> 0 | Z15: =E21 -> 0 | AA15: =E22 -> 0 | AB15: =E24 -> 0 | AC15: =E26 -> 0 | AD15: =E28 -> 0 | AE15: =E30 -> 0 | AF15: =E32 -> 0 | AG15: =E35 -> 0 | AH15: =E37 -> 0 | AI15: =E40 -> 0 | AJ15: =E42 -> 0 | AK15: =E44 -> 0 | AL15: =E47 -> 0 | AM15: =E49 -> 0 | AN15: =E52 -> 0 | AO15: =E55 -> 0 | AP15: =E58 -> 0 | AQ15: =K14 -> 0 | AR15: =K18 -> 0 | AS15: =K22 -> 0 | AT15: =K25 -> 0 | AU15: =K30 -> 0 | AV15: =K36 -> 0 | AW15: =K43 -> 0 | AX15: =K52 -> 65 | AY15: =Q14 -> 65 | AZ15: =AVERAGEIF(V15:AY15,"<>0") -> 65
A16: 2 | B16: al-Baqoroh : 142 - 252 | H16: Fathir | N16: Abasa
A17: 3 | B17: al-Baqoroh : 253 - 286 | H17: Yasin : 1 - 27 | N17: at-Takwiir
B18: Ali Imron : 1 - 91 | G18: 23 | H18: Yasin : 28 - 83 | N18: al-Infithar
A19: 4 | B19: Ali Imron : 92 - 200 | H19: ash-Shafat | N19: al-Muthaffifiin
B20: an-Nisaa : 1 - 23 | H20: Shad | N20: al-Insyiqaq
A21: 5 | B21: an-Nisaa : 24 - 147 | H21: az-Zumar : 1 - 31 | N21: al-Buruuj
A22: 6 | B22: an-Nisaa : 148 - 172 | G22: 24 | H22: az-Zumar : 32 - 75 | N22: ath-Thariq
B23: al-Maidah : 1 - 81 | H23: Ghafir | N23: al-A'laa
A24: 7 | B24: al-Maidah : 82 - 120 | H24: Fusshilat : 1 - 46 | N24: al-Ghasyiyah
B25: al-An'am : 1 - 110 | G25: 25 | H25: Fusshilat : 47 - 54 | N25: al-Fajr
A26: 8 | B26: al-An'am : 111 - 165 | H26: asy-Syuura | N26: al-Balad
B27: al-A'raf : 1 - 87 | H27: az-Zukhruf | N27: asy-Syams
A28: 9 | B28: al-A'raf : 88 - 206 | H28: ad-Dukhaan | N28: al-Lail
B29: al-Anfaal : 1 - 40 | H29: al-Jaatsiyah | N29: adh-Dhuhaa
A30: 10 | B30: al-Anfaal : 41 - 75 | G30: 26 | H30: al-Ahqaf | N30: asy-Syarh
B31: at-Taubah : 1 - 92 | H31: Muhammad | N31: at-Tiin
A32: 11 | B32: at-Taubah : 93 - 129 | H32: al-Fath | N32: al-'Alaq
B33: Yunus : 1 - 109 | H33: al-Hujuraat | N33: al-Qadr
B34: Huud : 1 - 5 | H34: Qaaf | N34: al-Bayyinah
A35: 12 | B35: Huud : 6 - 123 | H35: adz-Dzaariyaat: 1 - 30 | N35: al-Zalzalah
B36: Yusuf : 1 - 52 | G36: 27 | H36: adz-Dzaariyaat: 31 - 60 | N36: al-'Aadiyaat
A37: 13 | B37: Yusuf : 53 - 111 | H37: ath-Thuur | N37: al-Qari'ah
B38: ar-Ra'd : 1 - 43 | H38: an-Najm | N38: at-Takatsur
B39: Ibrahim : 1 - 52 | H39: al-Qomar | N39: al-'Ashr
A40: 14 | B40: al-Hijr : 1 - 69 | H40: ar-Rahman | N40: al-Humazah
B41: an-Nahl : 1 - 128 | H41: al-Waaqi'ah | N41: al-Fiil
A42: 15 | B42: al-Israa : 1 - 111 | H42: al-Hadiid | N42: al-Quraisy
B43: al-Kahfi : 1 - 74 | G43: 28 | H43: al-Mujaadilah | N43: al-Maa'uun
A44: 16 | B44: al-Kahfi : 75 - 110 | H44: al-Hasyr | N44: al-Kautsar
...

Sheet 9
A2: PONDOK PESANTREN DAARUS SALAF
A3: Nomor Statistik Pondok Pesantren : 510033110106
A4: Sekretariat: Masjid Ibnu Taimiyyah, Jl. Pandawa, Karang RT 04 RW 07, Sanggrahan, Grogol, Sukoharjo.
A6: Laporan Penilaian Hifzhul Qur'an
A7: Nama Santri | C7: MUHAMMAD ILYAS | M7: Tahun Ajaran | O7: 1446-1447 H / 2025-2026 M
A8: Nomor Induk Santri | C8: 2101112 | M8: Kelas/Jenjang | O8: 5 / ULAA
A9: NISN | C9: - | M9: Semester | O9: GENAP
A11: Juz | B11: Nama Surat | D11: Nilai | G11: Juz | H11: Nama Surat | J11: Nilai | M11: Juz | N11: Nama Surat | P11: Nilai | V11: Rekap Nilai | AZ11: Rerata
D12: K | E12: T | J12: K | K12: T | P12: K | Q12: T | V12: 1 | W12: 2 | X12: 3 | Y12: 4 | Z12: 5 | AA12: 6 | AB12: 7 | AC12: 8 | AD12: 9 | AE12: 10 | AF12: 11 | AG12: 12 | AH12: 13 | AI12: 14 | AJ12: 15 | AK12: 16 | AL12: 17 | AM12: 18 | AN12: 19 | AO12: 20 | AP12: 21 | AQ12: 22 | AR12: 23 | AS12: 24 | AT12: 25 | AU12: 26 | AV12: 27 | AW12: 28 | AX12: 29 | AY12: 30
A14: 1 | B14: al-Fatihah : 1 - 7 | G14: 22 | H14: al-Ahzab : 31 - 73 | M14: 30 | N14: an-Nabaa | P14: 85 | Q14: 65 | U14: Kelancaran | V14: =D14 -> 0 | W14: =D16 -> 0 | X14: =D17 -> 0 | Y14: =D19 -> 0 | Z14: =D21 -> 0 | AA14: =D22 -> 0 | AB14: =D24 -> 0 | AC14: =D26 -> 0 | AD14: =D28 -> 0 | AE14: =D30 -> 0 | AF14: =D32 -> 0 | AG14: =D35 -> 0 | AH14: =D37 -> 0 | AI14: =D40 -> 0 | AJ14: =D42 -> 0 | AK14: =D44 -> 0 | AL14: =D47 -> 0 | AM14: =D49 -> 0 | AN14: =D52 -> 0 | AO14: =D55 -> 0 | AP14: =D58 -> 0 | AQ14: =J14 -> 0 | AR14: =J18 -> 0 | AS14: =J22 -> 0 | AT14: =J25 -> 0 | AU14: =J30 -> 0 | AV14: =J36 -> 0 | AW14: =J43 -> 0 | AX14: =J52 -> 85 | AY14: =P14 -> 85 | AZ14: =AVERAGEIF(V14:AY14,">0") -> 85
B15: al-Baqoroh : 1 - 141 | H15: Saba' | N15: an-Naazi'aat | U15: Tajwid | V15: =E14 -> 0 | W15: =E16 -> 0 | X15: =E17 -> 0 | Y15: =E19 -> 0 | Z15: =E21 -> 0 | AA15: =E22 -> 0 | AB15: =E24 -> 0 | AC15: =E26 -> 0 | AD15: =E28 -> 0 | AE15: =E30 -> 0 | AF15: =E32 -> 0 | AG15: =E35 -> 0 | AH15: =E37 -> 0 | AI15: =E40 -> 0 | AJ15: =E42 -> 0 | AK15: =E44 -> 0 | AL15: =E47 -> 0 | AM15: =E49 -> 0 | AN15: =E52 -> 0 | AO15: =E55 -> 0 | AP15: =E58 -> 0 | AQ15: =K14 -> 0 | AR15: =K18 -> 0 | AS15: =K22 -> 0 | AT15: =K25 -> 0 | AU15: =K30 -> 0 | AV15: =K36 -> 0 | AW15: =K43 -> 0 | AX15: =K52 -> 65 | AY15: =Q14 -> 65 | AZ15: =AVERAGEIF(V15:AY15,">0") -> 65
A16: 2 | B16: al-Baqoroh : 142 - 252 | H16: Fathir | N16: Abasa
A17: 3 | B17: al-Baqoroh : 253 - 286 | H17: Yasin : 1 - 27 | N17: at-Takwiir
B18: Ali Imron : 1 - 91 | G18: 23 | H18: Yasin : 28 - 83 | N18: al-Infithar
A19: 4 | B19: Ali Imron : 92 - 200 | H19: ash-Shafat | N19: al-Muthaffifiin
B20: an-Nisaa : 1 - 23 | H20: Shad | N20: al-Insyiqaq
A21: 5 | B21: an-Nisaa : 24 - 147 | H21: az-Zumar : 1 - 31 | N21: al-Buruuj
A22: 6 | B22: an-Nisaa : 148 - 172 | G22: 24 | H22: az-Zumar : 32 - 75 | N22: ath-Thariq
B23: al-Maidah : 1 - 81 | H23: Ghafir | N23: al-A'laa
A24: 7 | B24: al-Maidah : 82 - 120 | H24: Fusshilat : 1 - 46 | N24: al-Ghasyiyah
B25: al-An'am : 1 - 110 | G25: 25 | H25: Fusshilat : 47 - 54 | N25: al-Fajr
A26: 8 | B26: al-An'am : 111 - 165 | H26: asy-Syuura | N26: al-Balad
B27: al-A'raf : 1 - 87 | H27: az-Zukhruf | N27: asy-Syams
A28: 9 | B28: al-A'raf : 88 - 206 | H28: ad-Dukhaan | N28: al-Lail
B29: al-Anfaal : 1 - 40 | H29: al-Jaatsiyah | N29: adh-Dhuhaa
A30: 10 | B30: al-Anfaal : 41 - 75 | G30: 26 | H30: al-Ahqaf | N30: asy-Syarh
B31: at-Taubah : 1 - 92 | H31: Muhammad | N31: at-Tiin
A32: 11 | B32: at-Taubah : 93 - 129 | H32: al-Fath | N32: al-'Alaq
B33: Yunus : 1 - 109 | H33: al-Hujuraat | N33: al-Qadr
B34: Huud : 1 - 5 | H34: Qaaf | N34: al-Bayyinah
A35: 12 | B35: Huud : 6 - 123 | H35: adz-Dzaariyaat: 1 - 30 | N35: al-Zalzalah
B36: Yusuf : 1 - 52 | G36: 27 | H36: adz-Dzaariyaat: 31 - 60 | N36: al-'Aadiyaat
A37: 13 | B37: Yusuf : 53 - 111 | H37: ath-Thuur | N37: al-Qari'ah
B38: ar-Ra'd : 1 - 43 | H38: an-Najm | N38: at-Takatsur
B39: Ibrahim : 1 - 52 | H39: al-Qomar | N39: al-'Ashr
A40: 14 | B40: al-Hijr : 1 - 69 | H40: ar-Rahman | N40: al-Humazah
B41: an-Nahl : 1 - 128 | H41: al-Waaqi'ah | N41: al-Fiil
A42: 15 | B42: al-Israa : 1 - 111 | H42: al-Hadiid | N42: al-Quraisy
B43: al-Kahfi : 1 - 74 | G43: 28 | H43: al-Mujaadilah | N43: al-Maa'uun
A44: 16 | B44: al-Kahfi : 75 - 110 | H44: al-Hasyr | N44: al-Kautsar
...

Sheet 10
A2: PONDOK PESANTREN DAARUS SALAF
A3: Nomor Statistik Pondok Pesantren : 510033110106
A4: Sekretariat: Masjid Ibnu Taimiyyah, Jl. Pandawa, Karang RT 04 RW 07, Sanggrahan, Grogol, Sukoharjo.
A6: Laporan Penilaian Hifzhul Qur'an
A7: Nama Santri | C7: YUNUS | M7: Tahun Ajaran | O7: 1446-1447 H / 2025-2026 M
A8: Nomor Induk Santri | C8: 2101113 | M8: Kelas/Jenjang | O8: 5 / ULAA
A9: NISN | C9: - | M9: Semester | O9: GENAP
A11: Juz | B11: Nama Surat | D11: Nilai | G11: Juz | H11: Nama Surat | J11: Nilai | M11: Juz | N11: Nama Surat | P11: Nilai | V11: Rekap Nilai | AZ11: Rerata
D12: K | E12: T | J12: K | K12: T | P12: K | Q12: T | V12: 1 | W12: 2 | X12: 3 | Y12: 4 | Z12: 5 | AA12: 6 | AB12: 7 | AC12: 8 | AD12: 9 | AE12: 10 | AF12: 11 | AG12: 12 | AH12: 13 | AI12: 14 | AJ12: 15 | AK12: 16 | AL12: 17 | AM12: 18 | AN12: 19 | AO12: 20 | AP12: 21 | AQ12: 22 | AR12: 23 | AS12: 24 | AT12: 25 | AU12: 26 | AV12: 27 | AW12: 28 | AX12: 29 | AY12: 30
A14: 1 | B14: al-Fatihah : 1 - 7 | G14: 22 | H14: al-Ahzab : 31 - 73 | M14: 30 | N14: an-Nabaa | P14: 90 | Q14: 70 | U14: Kelancaran | V14: =D14 -> 0 | W14: =D16 -> 0 | X14: =D17 -> 0 | Y14: =D19 -> 0 | Z14: =D21 -> 0 | AA14: =D22 -> 0 | AB14: =D24 -> 0 | AC14: =D26 -> 0 | AD14: =D28 -> 0 | AE14: =D30 -> 0 | AF14: =D32 -> 0 | AG14: =D35 -> 0 | AH14: =D37 -> 0 | AI14: =D40 -> 0 | AJ14: =D42 -> 0 | AK14: =D44 -> 0 | AL14: =D47 -> 0 | AM14: =D49 -> 0 | AN14: =D52 -> 0 | AO14: =D55 -> 0 | AP14: =D58 -> 0 | AQ14: =J14 -> 0 | AR14: =J18 -> 0 | AS14: =J22 -> 0 | AT14: =J25 -> 0 | AU14: =J30 -> 65 | AV14: =J36 -> 69 | AW14: =J43 -> 68 | AX14: =J52 -> 90 | AY14: =P14 -> 90 | AZ14: =AVERAGEIF(V14:AY14,">0") -> 76.4
B15: al-Baqoroh : 1 - 141 | H15: Saba' | N15: an-Naazi'aat | U15: Tajwid | V15: =E14 -> 0 | W15: =E16 -> 0 | X15: =E17 -> 0 | Y15: =E19 -> 0 | Z15: =E21 -> 0 | AA15: =E22 -> 0 | AB15: =E24 -> 0 | AC15: =E26 -> 0 | AD15: =E28 -> 0 | AE15: =E30 -> 0 | AF15: =E32 -> 0 | AG15: =E35 -> 0 | AH15: =E37 -> 0 | AI15: =E40 -> 0 | AJ15: =E42 -> 0 | AK15: =E44 -> 0 | AL15: =E47 -> 0 | AM15: =E49 -> 0 | AN15: =E52 -> 0 | AO15: =E55 -> 0 | AP15: =E58 -> 0 | AQ15: =K14 -> 0 | AR15: =K18 -> 0 | AS15: =K22 -> 0 | AT15: =K25 -> 0 | AU15: =K30 -> 70 | AV15: =K36 -> 70 | AW15: =K43 -> 70 | AX15: =K52 -> 70 | AY15: =Q14 -> 70 | AZ15: =AVERAGEIF(V15:AY15,"<>0") -> 70
A16: 2 | B16: al-Baqoroh : 142 - 252 | H16: Fathir | N16: Abasa
A17: 3 | B17: al-Baqoroh : 253 - 286 | H17: Yasin : 1 - 27 | N17: at-Takwiir
B18: Ali Imron : 1 - 91 | G18: 23 | H18: Yasin : 28 - 83 | N18: al-Infithar
A19: 4 | B19: Ali Imron : 92 - 200 | H19: ash-Shafat | N19: al-Muthaffifiin
B20: an-Nisaa : 1 - 23 | H20: Shad | N20: al-Insyiqaq
A21: 5 | B21: an-Nisaa : 24 - 147 | H21: az-Zumar : 1 - 31 | N21: al-Buruuj
A22: 6 | B22: an-Nisaa : 148 - 172 | G22: 24 | H22: az-Zumar : 32 - 75 | N22: ath-Thariq
B23: al-Maidah : 1 - 81 | H23: Ghafir | N23: al-A'laa
A24: 7 | B24: al-Maidah : 82 - 120 | H24: Fusshilat : 1 - 46 | N24: al-Ghasyiyah
B25: al-An'am : 1 - 110 | G25: 25 | H25: Fusshilat : 47 - 54 | N25: al-Fajr
A26: 8 | B26: al-An'am : 111 - 165 | H26: asy-Syuura | N26: al-Balad
B27: al-A'raf : 1 - 87 | H27: az-Zukhruf | N27: asy-Syams
A28: 9 | B28: al-A'raf : 88 - 206 | H28: ad-Dukhaan | N28: al-Lail
B29: al-Anfaal : 1 - 40 | H29: al-Jaatsiyah | N29: adh-Dhuhaa
A30: 10 | B30: al-Anfaal : 41 - 75 | G30: 26 | H30: al-Ahqaf | J30: 65 | K30: 70 | N30: asy-Syarh
B31: at-Taubah : 1 - 92 | H31: Muhammad | N31: at-Tiin
A32: 11 | B32: at-Taubah : 93 - 129 | H32: al-Fath | N32: al-'Alaq
B33: Yunus : 1 - 109 | H33: al-Hujuraat | N33: al-Qadr
B34: Huud : 1 - 5 | H34: Qaaf | N34: al-Bayyinah
A35: 12 | B35: Huud : 6 - 123 | H35: adz-Dzaariyaat: 1 - 30 | N35: al-Zalzalah
B36: Yusuf : 1 - 52 | G36: 27 | H36: adz-Dzaariyaat: 31 - 60 | J36: 69 | K36: 70 | N36: al-'Aadiyaat
A37: 13 | B37: Yusuf : 53 - 111 | H37: ath-Thuur | N37: al-Qari'ah
B38: ar-Ra'd : 1 - 43 | H38: an-Najm | N38: at-Takatsur
B39: Ibrahim : 1 - 52 | H39: al-Qomar | N39: al-'Ashr
A40: 14 | B40: al-Hijr : 1 - 69 | H40: ar-Rahman | N40: al-Humazah
B41: an-Nahl : 1 - 128 | H41: al-Waaqi'ah | N41: al-Fiil
A42: 15 | B42: al-Israa : 1 - 111 | H42: al-Hadiid | N42: al-Quraisy
B43: al-Kahfi : 1 - 74 | G43: 28 | H43: al-Mujaadilah | J43: 68 | K43: 70 | N43: al-Maa'uun
A44: 16 | B44: al-Kahfi : 75 - 110 | H44: al-Hasyr | N44: al-Kautsar
...

Sheet 11
A2: PONDOK PESANTREN DAARUS SALAF
A3: Nomor Statistik Pondok Pesantren : 510033110106
A4: Sekretariat: Masjid Ibnu Taimiyyah, Jl. Pandawa, Karang RT 04 RW 07, Sanggrahan, Grogol, Sukoharjo.
A6: Laporan Penilaian Hifzhul Qur'an
A7: Nama Santri | C7: HAMZAH | M7: Tahun Ajaran | O7: 1446-1447 H / 2025-2026 M
A8: Nomor Induk Santri | C8: 2202101 | M8: Kelas/Jenjang | O8: 5 / ULAA
A9: NISN | C9: - | M9: Semester | O9: GENAP
A11: Juz | B11: Nama Surat | D11: Nilai | G11: Juz | H11: Nama Surat | J11: Nilai | M11: Juz | N11: Nama Surat | P11: Nilai | V11: Rekap Nilai | AZ11: Rerata
D12: K | E12: T | J12: K | K12: T | P12: K | Q12: T | V12: 1 | W12: 2 | X12: 3 | Y12: 4 | Z12: 5 | AA12: 6 | AB12: 7 | AC12: 8 | AD12: 9 | AE12: 10 | AF12: 11 | AG12: 12 | AH12: 13 | AI12: 14 | AJ12: 15 | AK12: 16 | AL12: 17 | AM12: 18 | AN12: 19 | AO12: 20 | AP12: 21 | AQ12: 22 | AR12: 23 | AS12: 24 | AT12: 25 | AU12: 26 | AV12: 27 | AW12: 28 | AX12: 29 | AY12: 30
A14: 1 | B14: al-Fatihah : 1 - 7 | G14: 22 | H14: al-Ahzab : 31 - 73 | M14: 30 | N14: an-Nabaa | P14: 84 | Q14: 60 | U14: Kelancaran | V14: =D14 -> 0 | W14: =D16 -> 0 | X14: =D17 -> 0 | Y14: =D19 -> 0 | Z14: =D21 -> 0 | AA14: =D22 -> 0 | AB14: =D24 -> 0 | AC14: =D26 -> 0 | AD14: =D28 -> 0 | AE14: =D30 -> 0 | AF14: =D32 -> 0 | AG14: =D35 -> 0 | AH14: =D37 -> 0 | AI14: =D40 -> 0 | AJ14: =D42 -> 0 | AK14: =D44 -> 0 | AL14: =D47 -> 0 | AM14: =D49 -> 0 | AN14: =D52 -> 0 | AO14: =D55 -> 0 | AP14: =D58 -> 0 | AQ14: =J14 -> 0 | AR14: =J18 -> 0 | AS14: =J22 -> 0 | AT14: =J25 -> 0 | AU14: =J30 -> 0 | AV14: =J36 -> 0 | AW14: =J43 -> 0 | AX14: =J52 -> 85 | AY14: =P14 -> 84 | AZ14: =AVERAGEIF(V14:AY14,">0") -> 84.5
B15: al-Baqoroh : 1 - 141 | H15: Saba' | N15: an-Naazi'aat | U15: Tajwid | V15: =E14 -> 0 | W15: =E16 -> 0 | X15: =E17 -> 0 | Y15: =E19 -> 0 | Z15: =E21 -> 0 | AA15: =E22 -> 0 | AB15: =E24 -> 0 | AC15: =E26 -> 0 | AD15: =E28 -> 0 | AE15: =E30 -> 0 | AF15: =E32 -> 0 | AG15: =E35 -> 0 | AH15: =E37 -> 0 | AI15: =E40 -> 0 | AJ15: =E42 -> 0 | AK15: =E44 -> 0 | AL15: =E47 -> 0 | AM15: =E49 -> 0 | AN15: =E52 -> 0 | AO15: =E55 -> 0 | AP15: =E58 -> 0 | AQ15: =K14 -> 0 | AR15: =K18 -> 0 | AS15: =K22 -> 0 | AT15: =K25 -> 0 | AU15: =K30 -> 0 | AV15: =K36 -> 0 | AW15: =K43 -> 0 | AX15: =K52 -> 60 | AY15: =Q14 -> 60 | AZ15: =AVERAGEIF(V15:AY15,">0") -> 60
A16: 2 | B16: al-Baqoroh : 142 - 252 | H16: Fathir | N16: Abasa
A17: 3 | B17: al-Baqoroh : 253 - 286 | H17: Yasin : 1 - 27 | N17: at-Takwiir
B18: Ali Imron : 1 - 91 | G18: 23 | H18: Yasin : 28 - 83 | N18: al-Infithar
A19: 4 | B19: Ali Imron : 92 - 200 | H19: ash-Shafat | N19: al-Muthaffifiin
B20: an-Nisaa : 1 - 23 | H20: Shad | N20: al-Insyiqaq
A21: 5 | B21: an-Nisaa : 24 - 147 | H21: az-Zumar : 1 - 31 | N21: al-Buruuj
A22: 6 | B22: an-Nisaa : 148 - 172 | G22: 24 | H22: az-Zumar : 32 - 75 | N22: ath-Thariq
B23: al-Maidah : 1 - 81 | H23: Ghafir | N23: al-A'laa
A24: 7 | B24: al-Maidah : 82 - 120 | H24: Fusshilat : 1 - 46 | N24: al-Ghasyiyah
B25: al-An'am : 1 - 110 | G25: 25 | H25: Fusshilat : 47 - 54 | N25: al-Fajr
A26: 8 | B26: al-An'am : 111 - 165 | H26: asy-Syuura | N26: al-Balad
B27: al-A'raf : 1 - 87 | H27: az-Zukhruf | N27: asy-Syams
A28: 9 | B28: al-A'raf : 88 - 206 | H28: ad-Dukhaan | N28: al-Lail
B29: al-Anfaal : 1 - 40 | H29: al-Jaatsiyah | N29: adh-Dhuhaa
A30: 10 | B30: al-Anfaal : 41 - 75 | G30: 26 | H30: al-Ahqaf | N30: asy-Syarh
B31: at-Taubah : 1 - 92 | H31: Muhammad | N31: at-Tiin
A32: 11 | B32: at-Taubah : 93 - 129 | H32: al-Fath | N32: al-'Alaq
B33: Yunus : 1 - 109 | H33: al-Hujuraat | N33: al-Qadr
B34: Huud : 1 - 5 | H34: Qaaf | N34: al-Bayyinah
A35: 12 | B35: Huud : 6 - 123 | H35: adz-Dzaariyaat: 1 - 30 | N35: al-Zalzalah
B36: Yusuf : 1 - 52 | G36: 27 | H36: adz-Dzaariyaat: 31 - 60 | N36: al-'Aadiyaat
A37: 13 | B37: Yusuf : 53 - 111 | H37: ath-Thuur | N37: al-Qari'ah
B38: ar-Ra'd : 1 - 43 | H38: an-Najm | N38: at-Takatsur
B39: Ibrahim : 1 - 52 | H39: al-Qomar | N39: al-'Ashr
A40: 14 | B40: al-Hijr : 1 - 69 | H40: ar-Rahman | N40: al-Humazah
B41: an-Nahl : 1 - 128 | H41: al-Waaqi'ah | N41: al-Fiil
A42: 15 | B42: al-Israa : 1 - 111 | H42: al-Hadiid | N42: al-Quraisy
B43: al-Kahfi : 1 - 74 | G43: 28 | H43: al-Mujaadilah | N43: al-Maa'uun
A44: 16 | B44: al-Kahfi : 75 - 110 | H44: al-Hasyr | N44: al-Kautsar
...

Sheet Rekap
A1: Rekap Nilai Kelancaran Hifzhul Quran
A2: Rekap Nilai Kelancaran Hifzhul Quran
A4: No | B4: Nama | C4: Juz | AG4: Jumlah | AI4: Ranking | AJ4: Rerata Nilai | AK4: POIN | AL4: Ranking
C5: 1 | D5: 2 | E5: 3 | F5: 4 | G5: 5 | H5: 6 | I5: 7 | J5: 8 | K5: 9 | L5: 10 | M5: 11 | N5: 12 | O5: 13 | P5: 14 | Q5: 15 | R5: 16 | S5: 17 | T5: 18 | U5: 19 | V5: 20 | W5: 21 | X5: 22 | Y5: 23 | Z5: 24 | AA5: 25 | AB5: 26 | AC5: 27 | AD5: 28 | AE5: 29 | AF5: 30 | AG5: Hafalan | AI5: Berdasar | AJ5: Kelancaran | AL5: Berdasar
AG6: (JH) | AH6: Hafalan | AI6: Jml. Hafalan | AJ6: (RK) | AK6: (10 x JH) + RK | AL6: Jml Haf + Kelancrn
A8: 1 | B8: ='1'!$C$7 -> ABDULLOH ABBAS | C8: ='1'!$V$14 -> 0 | D8: ='1'!$W$14 -> 0 | E8: ='1'!$X$14 -> 0 | F8: ='1'!$Y$14 -> 0 | G8: ='1'!$Z$14 -> 0 | H8: ='1'!$AA$14 -> 0 | I8: ='1'!$AB$14 -> 0 | J8: ='1'!$AC$14 -> 0 | K8: ='1'!$AD$14 -> 0 | L8: ='1'!$AE$14 -> 0 | M8: ='1'!$AF$14 -> 0 | N8: ='1'!$AG$14 -> 0 | O8: ='1'!$AH$14 -> 0 | P8: ='1'!$AI$14 -> 0 | Q8: ='1'!$AJ$14 -> 0 | R8: ='1'!$AK$14 -> 0 | S8: ='1'!$AL$14 -> 0 | T8: ='1'!$AM$14 -> 0 | U8: ='1'!$AN$14 -> 0 | V8: ='1'!$AO$14 -> 0 | W8: ='1'!$AP$14 -> 0 | X8: ='1'!$AQ$14 -> 0 | Y8: ='1'!$AR$14 -> 0 | Z8: ='1'!$AS$14 -> 0 | AA8: ='1'!$AT$14 -> 0 | AB8: ='1'!$AU$14 -> 0 | AC8: ='1'!$AV$14 -> 90 | AD8: ='1'!$AW$14 -> 82 | AE8: ='1'!$AX$14 -> 90 | AF8: ='1'!$AY$14 -> 90 | AG8: =COUNTIF(C8:AF8,">0") -> 4 | AH8: juz | AI8: =RANK(AG8,$AG$8:$AG$18,0) -> 4 | AJ8: =AVERAGEIF(C8:AF8,">0") -> 88 | AK8: =10*AG8+AJ8 -> 128 | AL8: =RANK(AK8,$AK$8:$AK$18,0) -> 3
A9: 2 | B9: ='2'!$C$7 -> FALAH | C9: ='2'!$V$14 -> 0 | D9: ='2'!$W$14 -> 0 | E9: ='2'!$X$14 -> 0 | F9: ='2'!$Y$14 -> 0 | G9: ='2'!$Z$14 -> 0 | H9: ='2'!$AA$14 -> 0 | I9: ='2'!$AB$14 -> 0 | J9: ='2'!$AC$14 -> 0 | K9: ='2'!$AD$14 -> 0 | L9: ='2'!$AE$14 -> 0 | M9: ='2'!$AF$14 -> 0 | N9: ='2'!$AG$14 -> 0 | O9: ='2'!$AH$14 -> 0 | P9: ='2'!$AI$14 -> 0 | Q9: ='2'!$AJ$14 -> 0 | R9: ='2'!$AK$14 -> 0 | S9: ='2'!$AL$14 -> 0 | T9: ='2'!$AM$14 -> 0 | U9: ='2'!$AN$14 -> 0 | V9: ='2'!$AO$14 -> 0 | W9: ='2'!$AP$14 -> 0 | X9: ='2'!$AQ$14 -> 0 | Y9: ='2'!$AR$14 -> 0 | Z9: ='2'!$AS$14 -> 0 | AA9: ='2'!$AT$14 -> 0 | AB9: ='2'!$AU$14 -> 0 | AC9: ='2'!$AV$14 -> 0 | AD9: ='2'!$AW$14 -> 70 | AE9: ='2'!$AX$14 -> 85 | AF9: ='2'!$AY$14 -> 90 | AG9: =COUNTIF(C9:AF9,">0") -> 3 | AH9: juz | AI9: =RANK(AG9,$AG$8:$AG$18,0) -> 6 | AJ9: =AVERAGEIF(C9:AF9,">0") -> 81.666667 | AK9: =10*AG9+AJ9 -> 111.66667 | AL9: =RANK(AK9,$AK$8:$AK$18,0) -> 6
A10: 3 | B10: ='3'!$C$7 -> HAFIZH | C10: ='3'!$V$14 -> 0 | D10: ='3'!$W$14 -> 0 | E10: ='3'!$X$14 -> 0 | F10: ='3'!$Y$14 -> 0 | G10: ='3'!$Z$14 -> 0 | H10: ='3'!$AA$14 -> 0 | I10: ='3'!$AB$14 -> 0 | J10: ='3'!$AC$14 -> 0 | K10: ='3'!$AD$14 -> 0 | L10: ='3'!$AE$14 -> 0 | M10: ='3'!$AF$14 -> 0 | N10: ='3'!$AG$14 -> 0 | O10: ='3'!$AH$14 -> 0 | P10: ='3'!$AI$14 -> 0 | Q10: ='3'!$AJ$14 -> 0 | R10: ='3'!$AK$14 -> 0 | S10: ='3'!$AL$14 -> 0 | T10: ='3'!$AM$14 -> 0 | U10: ='3'!$AN$14 -> 0 | V10: ='3'!$AO$14 -> 0 | W10: ='3'!$AP$14 -> 0 | X10: ='3'!$AQ$14 -> 0 | Y10: ='3'!$AR$14 -> 0 | Z10: ='3'!$AS$14 -> 60 | AA10: ='3'!$AT$14 -> 65 | AB10: ='3'!$AU$14 -> 82 | AC10: ='3'!$AV$14 -> 76 | AD10: ='3'!$AW$14 -> 72 | AE10: ='3'!$AX$14 -> 88 | AF10: ='3'!$AY$14 -> 90 | AG10: =COUNTIF(C10:AF10,">0") -> 7 | AH10: juz | AI10: =RANK(AG10,$AG$8:$AG$18,0) -> 2 | AJ10: =AVERAGEIF(C10:AF10,">0") -> 76.142857 | AK10: =10*AG10+AJ10 -> 146.14286 | AL10: =RANK(AK10,$AK$8:$AK$18,0) -> 2
A11: 4 | B11: ='4'!$C$7 -> HARUN | C11: ='4'!$V$14 -> 0 | D11: ='4'!$W$14 -> 0 | E11: ='4'!$X$14 -> 0 | F11: ='4'!$Y$14 -> 0 | G11: ='4'!$Z$14 -> 0 | H11: ='4'!$AA$14 -> 0 | I11: ='4'!$AB$14 -> 0 | J11: ='4'!$AC$14 -> 0 | K11: ='4'!$AD$14 -> 0 | L11: ='4'!$AE$14 -> 0 | M11: ='4'!$AF$14 -> 0 | N11: ='4'!$AG$14 -> 0 | O11: ='4'!$AH$14 -> 0 | P11: ='4'!$AI$14 -> 0 | Q11: ='4'!$AJ$14 -> 0 | R11: ='4'!$AK$14 -> 0 | S11: ='4'!$AL$14 -> 0 | T11: ='4'!$AM$14 -> 0 | U11: ='4'!$AN$14 -> 0 | V11: ='4'!$AO$14 -> 0 | W11: ='4'!$AP$14 -> 0 | X11: ='4'!$AQ$14 -> 50 | Y11: ='4'!$AR$14 -> 57 | Z11: ='4'!$AS$14 -> 70 | AA11: ='4'!$AT$14 -> 67 | AB11: ='4'!$AU$14 -> 86 | AC11: ='4'!$AV$14 -> 90 | AD11: ='4'!$AW$14 -> 73 | AE11: ='4'!$AX$14 -> 90 | AF11: ='4'!$AY$14 -> 90 | AG11: =COUNTIF(C11:AF11,">0") -> 9 | AH11: juz | AI11: =RANK(AG11,$AG$8:$AG$18,0) -> 1 | AJ11: =AVERAGEIF(C11:AF11,">0") -> 74.777778 | AK11: =10*AG11+AJ11 -> 164.77778 | AL11: =RANK(AK11,$AK$8:$AK$18,0) -> 1
A12: 5 | B12: ='5'!$C$7 -> HASAN HAFIZHUDDIN | C12: ='5'!$V$14 -> 0 | D12: ='5'!$W$14 -> 0 | E12: ='5'!$X$14 -> 0 | F12: ='5'!$Y$14 -> 0 | G12: ='5'!$Z$14 -> 0 | H12: ='5'!$AA$14 -> 0 | I12: ='5'!$AB$14 -> 0 | J12: ='5'!$AC$14 -> 0 | K12: ='5'!$AD$14 -> 0 | L12: ='5'!$AE$14 -> 0 | M12: ='5'!$AF$14 -> 0 | N12: ='5'!$AG$14 -> 0 | O12: ='5'!$AH$14 -> 0 | P12: ='5'!$AI$14 -> 0 | Q12: ='5'!$AJ$14 -> 0 | R12: ='5'!$AK$14 -> 0 | S12: ='5'!$AL$14 -> 0 | T12: ='5'!$AM$14 -> 0 | U12: ='5'!$AN$14 -> 0 | V12: ='5'!$AO$14 -> 0 | W12: ='5'!$AP$14 -> 0 | X12: ='5'!$AQ$14 -> 0 | Y12: ='5'!$AR$14 -> 0 | Z12: ='5'!$AS$14 -> 0 | AA12: ='5'!$AT$14 -> 0 | AB12: ='5'!$AU$14 -> 0 | AC12: ='5'!$AV$14 -> 80 | AD12: ='5'!$AW$14 -> 85 | AE12: ='5'!$AX$14 -> 85 | AF12: ='5'!$AY$14 -> 90 | AG12: =COUNTIF(C12:AF12,">0") -> 4 | AH12: juz | AI12: =RANK(AG12,$AG$8:$AG$18,0) -> 4 | AJ12: =AVERAGEIF(C12:AF12,">0") -> 85 | AK12: =10*AG12+AJ12 -> 125 | AL12: =RANK(AK12,$AK$8:$AK$18,0) -> 5
A13: 6 | B13: ='6'!$C$7 -> IBROHIM AL ATSARY | C13: ='6'!$V$14 -> 0 | D13: ='6'!$W$14 -> 0 | E13: ='6'!$X$14 -> 0 | F13: ='6'!$Y$14 -> 0 | G13: ='6'!$Z$14 -> 0 | H13: ='6'!$AA$14 -> 0 | I13: ='6'!$AB$14 -> 0 | J13: ='6'!$AC$14 -> 0 | K13: ='6'!$AD$14 -> 0 | L13: ='6'!$AE$14 -> 0 | M13: ='6'!$AF$14 -> 0 | N13: ='6'!$AG$14 -> 0 | O13: ='6'!$AH$14 -> 0 | P13: ='6'!$AI$14 -> 0 | Q13: ='6'!$AJ$14 -> 0 | R13: ='6'!$AK$14 -> 0 | S13: ='6'!$AL$14 -> 0 | T13: ='6'!$AM$14 -> 0 | U13: ='6'!$AN$14 -> 0 | V13: ='6'!$AO$14 -> 0 | W13: ='6'!$AP$14 -> 0 | X13: ='6'!$AQ$14 -> 0 | Y13: ='6'!$AR$14 -> 0 | Z13: ='6'!$AS$14 -> 0 | AA13: ='6'!$AT$14 -> 0 | AB13: ='6'!$AU$14 -> 0 | AC13: ='6'!$AV$14 -> 0 | AD13: ='6'!$AW$14 -> 0 | AE13: ='6'!$AX$14 -> 59 | AF13: ='6'!$AY$14 -> 64 | AG13: =COUNTIF(C13:AF13,">0") -> 2 | AH13: juz | AI13: =RANK(AG13,$AG$8:$AG$18,0) -> 8 | AJ13: =AVERAGEIF(C13:AF13,">0") -> 61.5 | AK13: =10*AG13+AJ13 -> 81.5 | AL13: =RANK(AK13,$AK$8:$AK$18,0) -> 11
A14: 7 | B14: ='7'!$C$7 -> M. AUZAI ZIYAD | C14: ='7'!$V$14 -> 0 | D14: ='7'!$W$14 -> 0 | E14: ='7'!$X$14 -> 0 | F14: ='7'!$Y$14 -> 0 | G14: ='7'!$Z$14 -> 0 | H14: ='7'!$AA$14 -> 0 | I14: ='7'!$AB$14 -> 0 | J14: ='7'!$AC$14 -> 0 | K14: ='7'!$AD$14 -> 0 | L14: ='7'!$AE$14 -> 0 | M14: ='7'!$AF$14 -> 0 | N14: ='7'!$AG$14 -> 0 | O14: ='7'!$AH$14 -> 0 | P14: ='7'!$AI$14 -> 0 | Q14: ='7'!$AJ$14 -> 0 | R14: ='7'!$AK$14 -> 0 | S14: ='7'!$AL$14 -> 0 | T14: ='7'!$AM$14 -> 0 | U14: ='7'!$AN$14 -> 0 | V14: ='7'!$AO$14 -> 0 | W14: ='7'!$AP$14 -> 0 | X14: ='7'!$AQ$14 -> 0 | Y14: ='7'!$AR$14 -> 0 | Z14: ='7'!$AS$14 -> 0 | AA14: ='7'!$AT$14 -> 0 | AB14: ='7'!$AU$14 -> 0 | AC14: ='7'!$AV$14 -> 0 | AD14: ='7'!$AW$14 -> 53 | AE14: ='7'!$AX$14 -> 80 | AF14: ='7'!$AY$14 -> 80 | AG14: =COUNTIF(C14:AF14,">0") -> 3 | AH14: juz | AI14: =RANK(AG14,$AG$8:$AG$18,0) -> 6 | AJ14: =AVERAGEIF(C14:AF14,">0") -> 71 | AK14: =10*AG14+AJ14 -> 101 | AL14: =RANK(AK14,$AK$8:$AK$18,0) -> 9
A15: 8 | B15: ='8'!$C$7 -> MUHAMMAD FAKIH | C15: ='8'!$V$14 -> 0 | D15: ='8'!$W$14 -> 0 | E15: ='8'!$X$14 -> 0 | F15: ='8'!$Y$14 -> 0 | G15: ='8'!$Z$14 -> 0 | H15: ='8'!$AA$14 -> 0 | I15: ='8'!$AB$14 -> 0 | J15: ='8'!$AC$14 -> 0 | K15: ='8'!$AD$14 -> 0 | L15: ='8'!$AE$14 -> 0 | M15: ='8'!$AF$14 -> 0 | N15: ='8'!$AG$14 -> 0 | O15: ='8'!$AH$14 -> 0 | P15: ='8'!$AI$14 -> 0 | Q15: ='8'!$AJ$14 -> 0 | R15: ='8'!$AK$14 -> 0 | S15: ='8'!$AL$14 -> 0 | T15: ='8'!$AM$14 -> 0 | U15: ='8'!$AN$14 -> 0 | V15: ='8'!$AO$14 -> 0 | W15: ='8'!$AP$14 -> 0 | X15: ='8'!$AQ$14 -> 0 | Y15: ='8'!$AR$14 -> 0 | Z15: ='8'!$AS$14 -> 0 | AA15: ='8'!$AT$14 -> 0 | AB15: ='8'!$AU$14 -> 0 | AC15: ='8'!$AV$14 -> 0 | AD15: ='8'!$AW$14 -> 0 | AE15: ='8'!$AX$14 -> 75 | AF15: ='8'!$AY$14 -> 85 | AG15: =COUNTIF(C15:AF15,">0") -> 2 | AH15: juz | AI15: =RANK(AG15,$AG$8:$AG$18,0) -> 8 | AJ15: =AVERAGEIF(C15:AF15,">0") -> 80 | AK15: =10*AG15+AJ15 -> 100 | AL15: =RANK(AK15,$AK$8:$AK$18,0) -> 10
A16: 9 | B16: ='9'!$C$7 -> MUHAMMAD ILYAS | C16: ='9'!$V$14 -> 0 | D16: ='9'!$W$14 -> 0 | E16: ='9'!$X$14 -> 0 | F16: ='9'!$Y$14 -> 0 | G16: ='9'!$Z$14 -> 0 | H16: ='9'!$AA$14 -> 0 | I16: ='9'!$AB$14 -> 0 | J16: ='9'!$AC$14 -> 0 | K16: ='9'!$AD$14 -> 0 | L16: ='9'!$AE$14 -> 0 | M16: ='9'!$AF$14 -> 0 | N16: ='9'!$AG$14 -> 0 | O16: ='9'!$AH$14 -> 0 | P16: ='9'!$AI$14 -> 0 | Q16: ='9'!$AJ$14 -> 0 | R16: ='9'!$AK$14 -> 0 | S16: ='9'!$AL$14 -> 0 | T16: ='9'!$AM$14 -> 0 | U16: ='9'!$AN$14 -> 0 | V16: ='9'!$AO$14 -> 0 | W16: ='9'!$AP$14 -> 0 | X16: ='9'!$AQ$14 -> 0 | Y16: ='9'!$AR$14 -> 0 | Z16: ='9'!$AS$14 -> 0 | AA16: ='9'!$AT$14 -> 0 | AB16: ='9'!$AU$14 -> 0 | AC16: ='9'!$AV$14 -> 0 | AD16: ='9'!$AW$14 -> 0 | AE16: ='9'!$AX$14 -> 85 | AF16: ='9'!$AY$14 -> 85 | AG16: =COUNTIF(C16:AF16,">0") -> 2 | AH16: juz | AI16: =RANK(AG16,$AG$8:$AG$18,0) -> 8 | AJ16: =AVERAGEIF(C16:AF16,">0") -> 85 | AK16: =10*AG16+AJ16 -> 105 | AL16: =RANK(AK16,$AK$8:$AK$18,0) -> 7
A17: 10 | B17: ='10'!$C$7 -> YUNUS | C17: ='10'!$V$14 -> 0 | D17: ='10'!$W$14 -> 0 | E17: ='10'!$X$14 -> 0 | F17: ='10'!$Y$14 -> 0 | G17: ='10'!$Z$14 -> 0 | H17: ='10'!$AA$14 -> 0 | I17: ='10'!$AB$14 -> 0 | J17: ='10'!$AC$14 -> 0 | K17: ='10'!$AD$14 -> 0 | L17: ='10'!$AE$14 -> 0 | M17: ='10'!$AF$14 -> 0 | N17: ='10'!$AG$14 -> 0 | O17: ='10'!$AH$14 -> 0 | P17: ='10'!$AI$14 -> 0 | Q17: ='10'!$AJ$14 -> 0 | R17: ='10'!$AK$14 -> 0 | S17: ='10'!$AL$14 -> 0 | T17: ='10'!$AM$14 -> 0 | U17: ='10'!$AN$14 -> 0 | V17: ='10'!$AO$14 -> 0 | W17: ='10'!$AP$14 -> 0 | X17: ='10'!$AQ$14 -> 0 | Y17: ='10'!$AR$14 -> 0 | Z17: ='10'!$AS$14 -> 0 | AA17: ='10'!$AT$14 -> 0 | AB17: ='10'!$AU$14 -> 65 | AC17: ='10'!$AV$14 -> 69 | AD17: ='10'!$AW$14 -> 68 | AE17: ='10'!$AX$14 -> 90 | AF17: ='10'!$AY$14 -> 90 | AG17: =COUNTIF(C17:AF17,">0") -> 5 | AH17: juz | AI17: =RANK(AG17,$AG$8:$AG$18,0) -> 3 | AJ17: =AVERAGEIF(C17:AF17,">0") -> 76.4 | AK17: =10*AG17+AJ17 -> 126.4 | AL17: =RANK(AK17,$AK$8:$AK$18,0) -> 4
A18: 11 | B18: ='11'!$C$7 -> HAMZAH | C18: ='11'!$V$14 -> 0 | D18: ='11'!$W$14 -> 0 | E18: ='11'!$X$14 -> 0 | F18: ='11'!$Y$14 -> 0 | G18: ='11'!$Z$14 -> 0 | H18: ='11'!$AA$14 -> 0 | I18: ='11'!$AB$14 -> 0 | J18: ='11'!$AC$14 -> 0 | K18: ='11'!$AD$14 -> 0 | L18: ='11'!$AE$14 -> 0 | M18: ='11'!$AF$14 -> 0 | N18: ='11'!$AG$14 -> 0 | O18: ='11'!$AH$14 -> 0 | P18: ='11'!$AI$14 -> 0 | Q18: ='11'!$AJ$14 -> 0 | R18: ='11'!$AK$14 -> 0 | S18: ='11'!$AL$14 -> 0 | T18: ='11'!$AM$14 -> 0 | U18: ='11'!$AN$14 -> 0 | V18: ='11'!$AO$14 -> 0 | W18: ='11'!$AP$14 -> 0 | X18: ='11'!$AQ$14 -> 0 | Y18: ='11'!$AR$14 -> 0 | Z18: ='11'!$AS$14 -> 0 | AA18: ='11'!$AT$14 -> 0 | AB18: ='11'!$AU$14 -> 0 | AC18: ='11'!$AV$14 -> 0 | AD18: ='11'!$AW$14 -> 0 | AE18: ='11'!$AX$14 -> 85 | AF18: ='11'!$AY$14 -> 84 | AG18: =COUNTIF(C18:AF18,">0") -> 2 | AH18: juz | AI18: =RANK(AG18,$AG$8:$AG$18,0) -> 8 | AJ18: =AVERAGEIF(C18:AF18,">0") -> 84.5 | AK18: =10*AG18+AJ18 -> 104.5 | AL18: =RANK(AK18,$AK$8:$AK$18,0) -> 8
